<?xml version="1.0" ?>
<!-- =================================================================================== -->
<!-- |    This document was autogenerated by xacro from /home/martzi/yang_ws/install/system_description/share/system_description/urdf/robot_system_description.urdf.xacro | -->
<!-- |    EDITING THIS FILE BY HAND IS NOT RECOMMENDED                                 | -->
<!-- =================================================================================== -->
<robot name="ur"
	xmlns:layer1="urn:ietf:params:xml:ns:yang:layer1"
	xmlns:layer2="urn:ietf:params:xml:ns:yang:layer2"
	xmlns:robot-network="urn:ietf:params:xml:ns:yang:robot-network"
	xmlns:robot-network-topology="urn:ietf:params:xml:ns:yang:robot-network-topology">
	<!-- Base UR robot series xacro macro.
[instance_validator-1] NOTE this is NOT a URDF. It cannot directly be loaded by consumers expecting a flattened '.urdf' file. See the top-level '.xacro' for that (but note that .xacro must still be processed by the xacro command).
[instance_validator-1] This file models the base kinematic chain of a UR robot, which then gets parameterised by various configuration files to convert it into a UR3(e), UR5(e), UR10(e) or UR16e.
[instance_validator-1] NOTE the default kinematic parameters (i.e., link lengths, frame locations, offsets, etc) do not correspond to any particular robot. They are defaults only. There WILL be non-zero offsets between the Forward Kinematics results in TF (i.e., robot_state_publisher) and the values reported by the Teach Pendant.
[instance_validator-1] For accurate (and robot-specific) transforms, the 'kinematics_parameters_file' parameter MUST point to a .yaml file containing the appropriate values for the targeted robot.
[instance_validator-1] If using the UniversalRobots/Universal_Robots_ROS_Driver, follow the steps described in the readme of that repository to extract the kinematic calibration from the controller and generate the required .yaml file.
[instance_validator-1] Main author of the migration to yaml configs Ludovic Delval.
[instance_validator-1] Contributors to previous versions (in no particular order)
[instance_validator-1] - Denis Stogl - Lovro Ivanov - Felix Messmer - Kelsey Hawkins - Wim Meeussen - Shaun Edwards - Nadia Hammoudeh Garcia - Dave Hershberger - G. vd. Hoorn - Philip Long - Dave Coleman - Miguel Prada - Mathias Luedtke - Marcel Schnirring - Felix von Drigalski - Felix Exner - Jimmy Da Silva - Ajit Krisshna N L - Muhammad Asif Rana -->
	<!-- NOTE the macro defined in this file is NOT part of the public API of this package. Users CANNOT rely on this file being available, or stored in this location. Nor can they rely on the existence of the macro. -->
	<material name="aluminum">
		<color rgba="0.5 0.5 0.5 1"/>
	</material>
	<material name="plastic">
		<color rgba="0.1 0.1 0.1 1"/>
	</material>
	<!-- create link fixed to the "world" -->
	<link name="world"/>
	<joint name="controlbox" type="fixed">
		<origin rpy="0 3.141592653589793 3.141592653589793" xyz="-1.5 0 0.1"/>
		<parent link="base_link"/>
		<child link="urcontrolbox_link"/>
	</joint>
	<link name="urcontrolbox_link">
		<visual>
			<origin rpy="0 0 0" xyz="0 0 0"/>
			<geometry>
				<mesh filename="file:///home/martzi/yang_ws/install/ur_description/share/ur_description/meshes/common/simplify_control-box.stl" scale="0.001 0.001 0.001"/>
			</geometry>
			<!-- <material name="plastic"/> -->
		</visual>
		<collision>
			<origin rpy="0 0 0" xyz="0 0 0"/>
			<geometry>
				<mesh filename="file:///home/martzi/yang_ws/install/ur_description/share/ur_description/meshes/common/simplify_control-box.stl" scale="0.001 0.001 0.001"/>
			</geometry>
		</collision>
	</link>
	<joint name="ethernet0_frame" type="fixed">
		<parent link="urcontrolbox_link"/>
		<child link="ethernet0_link"/>
		<origin rpy="0 0 0" xyz="-0.1 0 0.1"/>
	</joint>
	<link name="ethernet0_link">
		<visual>
			<!-- y = -g,  -->
			<origin rpy="0 0 0" xyz="0.02 0 -0.03"/>
			<geometry>
				<mesh filename="file:///home/martzi/yang_ws/install/interface-description/share/interface-description/meshes/rj45-female.stl" scale="0.001 0.001 0.001"/>
			</geometry>
		</visual>
		<collision>
			<origin rpy="0 0 0" xyz="0.02 0 -0.03"/>
			<geometry>
				<mesh filename="file:///home/martzi/yang_ws/install/interface-description/share/interface-description/meshes/rj45-female.stl" scale="0.001 0.001 0.001"/>
			</geometry>
		</collision>
	</link>
	<link name="usb20_0_link"/>
	<joint name="usb20_0_frame" type="fixed">
		<parent link="urcontrolbox_link"/>
		<child link="usb20_0_link"/>
		<origin rpy="0 0 0" xyz="0 0 0.1"/>
	</joint>
	<link name="usb30_0_link"/>
	<joint name="usb30_0_frame" type="fixed">
		<parent link="urcontrolbox_link"/>
		<child link="usb30_0_link"/>
		<origin rpy="0 0 0" xyz="0.1 0 0.1"/>
	</joint>
	<yang>
		<!-- UR3e controlbox L2 network topology -->
		<robot-network:networks>
			<network-id>network_level</network-id>
			<layer2:l2-topology>
				<element>template</element>
			</layer2:l2-topology>
			<supporting-network>
				<network-ref>device_level</network-ref> <!-- 치ltal치nosan csak device-level -->
				<tf-parent>base_link</tf-parent>
			</supporting-network>
			<node>
				<!-- UR3e controlbox @ L2 -->
				<node-id>controlbox_L2</node-id>
				<layer2:l2-node-attributes>
					<bandwidth>1</bandwidth>
					<delay>2</delay>
				</layer2:l2-node-attributes>
				<supporting-node>
					<network-ref>device_level</network-ref>
					<node-ref>controlbox_L1</node-ref>
				</supporting-node>
				<robot-network-topology:termination-point>
					<tp-id>usb30_1</tp-id>
					<supporting-termination-point>
						<network-ref>device_level</network-ref> <!-- 치ltal치nosan csak device-level -->
						<node-ref>controlbox_L1</node-ref>
						<tp-ref>usb30_1</tp-ref>
					</supporting-termination-point>
					<layer2:l2-termination-point-attributes>
						<tp-type>usb30</tp-type>
						<bandwidth>4800</bandwidth>
						<jitter>8</jitter>
						<packet_loss>0.005</packet_loss>
						<reliability>0.98</reliability>
						<cost>25</cost>
					</layer2:l2-termination-point-attributes>
				</robot-network-topology:termination-point>
				<robot-network-topology:termination-point>
					<tp-id>usb20_1</tp-id>
					<supporting-termination-point>
						<network-ref>device_level</network-ref>
						<node-ref>controlbox_L1</node-ref>
						<tp-ref>usb20_1</tp-ref>
					</supporting-termination-point>
					<layer2:l2-termination-point-attributes>
						<tp-type>usb20</tp-type>
						<bandwidth>480</bandwidth>
						<jitter>15</jitter>
						<packet_loss>0.02</packet_loss>
						<reliability>0.9</reliability>
						<cost>5</cost>
					</layer2:l2-termination-point-attributes>
				</robot-network-topology:termination-point>
				<robot-network-topology:termination-point>
					<tp-id>eth_1</tp-id>
					<supporting-termination-point>
						<network-ref>device_level</network-ref>
						<node-ref>controlbox_L1</node-ref>
						<tp-ref>eth_1</tp-ref>
					</supporting-termination-point>
					<layer2:l2-termination-point-attributes>
						<tp-type>cat5e</tp-type>
						<bandwidth>1000</bandwidth>
						<jitter>10</jitter>
						<packet_loss>0.01</packet_loss>
						<reliability>0.95</reliability>
						<cost>30</cost>
					</layer2:l2-termination-point-attributes>
				</robot-network-topology:termination-point>
			</node>
		</robot-network:networks>
		<!-- UR3e controlbox L1 network topology -->
		<robot-network:networks>
			<network-id>device_level</network-id>
			<layer1:l1-topology>
				<element>template</element>
			</layer1:l1-topology>
			<node>
				<node-id>controlbox_L1</node-id>
				<layer1:l1-node-attributes>
					<device-type>controlbox</device-type>
					<phy-port-num>3</phy-port-num>
					<wireless-access>0</wireless-access>
				</layer1:l1-node-attributes>
				<robot-network-topology:termination-point>
					<tp-id>usb30_1</tp-id>
					<layer1:l1-termination-point-attributes>
						<connector-type>usb-std_A</connector-type>
						<connector-format>female</connector-format>
					</layer1:l1-termination-point-attributes>
				</robot-network-topology:termination-point>
				<robot-network-topology:termination-point>
					<tp-id>usb20_1</tp-id>
					<layer1:l1-termination-point-attributes>
						<connector-type>usb-std_A</connector-type>
						<connector-format>female</connector-format>
					</layer1:l1-termination-point-attributes>
				</robot-network-topology:termination-point>
				<robot-network-topology:termination-point>
					<tp-id>eth_1</tp-id>
					<layer1:l1-termination-point-attributes>
						<connector-type>rj45</connector-type>
						<connector-format>female</connector-format>
					</layer1:l1-termination-point-attributes>
				</robot-network-topology:termination-point>
			</node>
		</robot-network:networks>
	</yang>
	<ros2_control name="ur" type="system">
		<hardware>
			<plugin>ur_robot_driver/URPositionHardwareInterface</plugin>
			<param name="robot_ip">0.0.0.0</param>
			<param name="script_filename"></param>
			<param name="output_recipe_filename"></param>
			<param name="input_recipe_filename"></param>
			<param name="headless_mode">False</param>
			<param name="reverse_port">50001</param>
			<param name="script_sender_port">50002</param>
			<param name="reverse_ip">0.0.0.0</param>
			<param name="script_command_port">50004</param>
			<param name="trajectory_port">50003</param>
			<param name="tf_prefix"></param>
			<param name="non_blocking_read">False</param>
			<param name="servoj_gain">2000</param>
			<param name="servoj_lookahead_time">0.03</param>
			<param name="use_tool_communication">False</param>
			<param name="kinematics/hash">calib_16756443741236045476</param>
			<param name="tool_voltage">0</param>
			<param name="tool_parity">0</param>
			<param name="tool_baud_rate">115200</param>
			<param name="tool_stop_bits">1</param>
			<param name="tool_rx_idle_chars">1.5</param>
			<param name="tool_tx_idle_chars">3.5</param>
			<param name="tool_device_name">/tmp/ttyUR</param>
			<param name="tool_tcp_port">54321</param>
			<param name="keep_alive_count">2</param>
		</hardware>
		<joint name="shoulder_pan_joint">
			<command_interface name="position">
				<param name="min">{-2*pi}</param>
				<param name="max">{2*pi}</param>
			</command_interface>
			<command_interface name="velocity">
				<param name="min">-3.15</param>
				<param name="max">3.15</param>
			</command_interface>
			<state_interface name="position">
				<!-- initial position for the FakeSystem and simulation -->
				<param name="initial_value">0.0</param>
			</state_interface>
			<state_interface name="velocity"/>
			<state_interface name="effort"/>
		</joint>
		<joint name="shoulder_lift_joint">
			<command_interface name="position">
				<param name="min">{-2*pi}</param>
				<param name="max">{2*pi}</param>
			</command_interface>
			<command_interface name="velocity">
				<param name="min">-3.15</param>
				<param name="max">3.15</param>
			</command_interface>
			<state_interface name="position">
				<!-- initial position for the FakeSystem and simulation -->
				<param name="initial_value">-1.57</param>
			</state_interface>
			<state_interface name="velocity"/>
			<state_interface name="effort"/>
		</joint>
		<joint name="elbow_joint">
			<command_interface name="position">
				<param name="min">{-pi}</param>
				<param name="max">{pi}</param>
			</command_interface>
			<command_interface name="velocity">
				<param name="min">-3.15</param>
				<param name="max">3.15</param>
			</command_interface>
			<state_interface name="position">
				<!-- initial position for the FakeSystem and simulation -->
				<param name="initial_value">0.0</param>
			</state_interface>
			<state_interface name="velocity"/>
			<state_interface name="effort"/>
		</joint>
		<joint name="wrist_1_joint">
			<command_interface name="position">
				<param name="min">{-2*pi}</param>
				<param name="max">{2*pi}</param>
			</command_interface>
			<command_interface name="velocity">
				<param name="min">-3.2</param>
				<param name="max">3.2</param>
			</command_interface>
			<state_interface name="position">
				<!-- initial position for the FakeSystem and simulation -->
				<param name="initial_value">-1.57</param>
			</state_interface>
			<state_interface name="velocity"/>
			<state_interface name="effort"/>
		</joint>
		<joint name="wrist_2_joint">
			<command_interface name="position">
				<param name="min">{-2*pi}</param>
				<param name="max">{2*pi}</param>
			</command_interface>
			<command_interface name="velocity">
				<param name="min">-3.2</param>
				<param name="max">3.2</param>
			</command_interface>
			<state_interface name="position">
				<!-- initial position for the FakeSystem and simulation -->
				<param name="initial_value">0.0</param>
			</state_interface>
			<state_interface name="velocity"/>
			<state_interface name="effort"/>
		</joint>
		<joint name="wrist_3_joint">
			<command_interface name="position">
				<param name="min">{-2*pi}</param>
				<param name="max">{2*pi}</param>
			</command_interface>
			<command_interface name="velocity">
				<param name="min">-3.2</param>
				<param name="max">3.2</param>
			</command_interface>
			<state_interface name="position">
				<!-- initial position for the FakeSystem and simulation -->
				<param name="initial_value">0.0</param>
			</state_interface>
			<state_interface name="velocity"/>
			<state_interface name="effort"/>
		</joint>
		<sensor name="tcp_fts_sensor">
			<state_interface name="force.x"/>
			<state_interface name="force.y"/>
			<state_interface name="force.z"/>
			<state_interface name="torque.x"/>
			<state_interface name="torque.y"/>
			<state_interface name="torque.z"/>
		</sensor>
		<!-- NOTE The following are joints used only for testing with fake hardware and will change in the future -->
		<gpio name="speed_scaling">
			<state_interface name="speed_scaling_factor"/>
			<param name="initial_speed_scaling_factor">1</param>
			<command_interface name="target_speed_fraction_cmd"/>
			<command_interface name="target_speed_fraction_async_success"/>
		</gpio>
		<gpio name="gpio">
			<command_interface name="standard_digital_output_cmd_0"/>
			<command_interface name="standard_digital_output_cmd_1"/>
			<command_interface name="standard_digital_output_cmd_2"/>
			<command_interface name="standard_digital_output_cmd_3"/>
			<command_interface name="standard_digital_output_cmd_4"/>
			<command_interface name="standard_digital_output_cmd_5"/>
			<command_interface name="standard_digital_output_cmd_6"/>
			<command_interface name="standard_digital_output_cmd_7"/>
			<command_interface name="standard_digital_output_cmd_8"/>
			<command_interface name="standard_digital_output_cmd_9"/>
			<command_interface name="standard_digital_output_cmd_10"/>
			<command_interface name="standard_digital_output_cmd_11"/>
			<command_interface name="standard_digital_output_cmd_12"/>
			<command_interface name="standard_digital_output_cmd_13"/>
			<command_interface name="standard_digital_output_cmd_14"/>
			<command_interface name="standard_digital_output_cmd_15"/>
			<command_interface name="standard_digital_output_cmd_16"/>
			<command_interface name="standard_digital_output_cmd_17"/>
			<command_interface name="standard_analog_output_cmd_0"/>
			<command_interface name="standard_analog_output_cmd_1"/>
			<command_interface name="tool_voltage_cmd"/>
			<command_interface name="io_async_success"/>
			<state_interface name="digital_output_0"/>
			<state_interface name="digital_output_1"/>
			<state_interface name="digital_output_2"/>
			<state_interface name="digital_output_3"/>
			<state_interface name="digital_output_4"/>
			<state_interface name="digital_output_5"/>
			<state_interface name="digital_output_6"/>
			<state_interface name="digital_output_7"/>
			<state_interface name="digital_output_8"/>
			<state_interface name="digital_output_9"/>
			<state_interface name="digital_output_10"/>
			<state_interface name="digital_output_11"/>
			<state_interface name="digital_output_12"/>
			<state_interface name="digital_output_13"/>
			<state_interface name="digital_output_14"/>
			<state_interface name="digital_output_15"/>
			<state_interface name="digital_output_16"/>
			<state_interface name="digital_output_17"/>
			<state_interface name="digital_input_0"/>
			<state_interface name="digital_input_1"/>
			<state_interface name="digital_input_2"/>
			<state_interface name="digital_input_3"/>
			<state_interface name="digital_input_4"/>
			<state_interface name="digital_input_5"/>
			<state_interface name="digital_input_6"/>
			<state_interface name="digital_input_7"/>
			<state_interface name="digital_input_8"/>
			<state_interface name="digital_input_9"/>
			<state_interface name="digital_input_10"/>
			<state_interface name="digital_input_11"/>
			<state_interface name="digital_input_12"/>
			<state_interface name="digital_input_13"/>
			<state_interface name="digital_input_14"/>
			<state_interface name="digital_input_15"/>
			<state_interface name="digital_input_16"/>
			<state_interface name="digital_input_17"/>
			<state_interface name="standard_analog_output_0"/>
			<state_interface name="standard_analog_output_1"/>
			<state_interface name="standard_analog_input_0"/>
			<state_interface name="standard_analog_input_1"/>
			<state_interface name="analog_io_type_0"/>
			<state_interface name="analog_io_type_1"/>
			<state_interface name="analog_io_type_2"/>
			<state_interface name="analog_io_type_3"/>
			<state_interface name="tool_mode"/>
			<state_interface name="tool_output_voltage"/>
			<state_interface name="tool_output_current"/>
			<state_interface name="tool_temperature"/>
			<state_interface name="tool_analog_input_0"/>
			<state_interface name="tool_analog_input_1"/>
			<state_interface name="tool_analog_input_type_0"/>
			<state_interface name="tool_analog_input_type_1"/>
			<state_interface name="robot_mode"/>
			<state_interface name="robot_status_bit_0"/>
			<state_interface name="robot_status_bit_1"/>
			<state_interface name="robot_status_bit_2"/>
			<state_interface name="robot_status_bit_3"/>
			<state_interface name="safety_mode"/>
			<state_interface name="safety_status_bit_0"/>
			<state_interface name="safety_status_bit_1"/>
			<state_interface name="safety_status_bit_2"/>
			<state_interface name="safety_status_bit_3"/>
			<state_interface name="safety_status_bit_4"/>
			<state_interface name="safety_status_bit_5"/>
			<state_interface name="safety_status_bit_6"/>
			<state_interface name="safety_status_bit_7"/>
			<state_interface name="safety_status_bit_8"/>
			<state_interface name="safety_status_bit_9"/>
			<state_interface name="safety_status_bit_10"/>
			<state_interface name="program_running"/>
		</gpio>
		<gpio name="payload">
			<command_interface name="mass"/>
			<command_interface name="cog.x"/>
			<command_interface name="cog.y"/>
			<command_interface name="cog.z"/>
			<command_interface name="payload_async_success"/>
		</gpio>
		<gpio name="resend_robot_program">
			<command_interface name="resend_robot_program_cmd"/>
			<command_interface name="resend_robot_program_async_success"/>
		</gpio>
		<gpio name="hand_back_control">
			<command_interface name="hand_back_control_cmd"/>
			<command_interface name="hand_back_control_async_success"/>
		</gpio>
		<gpio name="zero_ftsensor">
			<command_interface name="zero_ftsensor_cmd"/>
			<command_interface name="zero_ftsensor_async_success"/>
		</gpio>
		<gpio name="system_interface">
			<state_interface name="initialized"/>
		</gpio>
	</ros2_control>
	<!-- Add URDF transmission elements (for ros_control) -->
	<!--<xacro:ur_arm_transmission prefix="${prefix}" hw_interface="${transmission_hw_interface}" />-->
	<!-- Placeholder for ros2_control transmission which don't yet exist -->
	<!-- links -  main serial chain -->
	<link name="base_link"/>
	<link name="base_link_inertia">
		<visual>
			<origin rpy="0 0 3.141592653589793" xyz="0 0 0"/>
			<geometry>
				<mesh filename="package://ur_description/meshes/ur3e/visual/base.dae"/>
			</geometry>
		</visual>
		<collision>
			<origin rpy="0 0 3.141592653589793" xyz="0 0 0"/>
			<geometry>
				<mesh filename="package://ur_description/meshes/ur3e/collision/base.stl"/>
			</geometry>
		</collision>
		<inertial>
			<mass value="2.0"/>
			<origin rpy="0 0 0" xyz="0 0 0"/>
			<inertia ixx="0.0030531654454" ixy="0.0" ixz="0.0" iyy="0.0030531654454" iyz="0.0" izz="0.005625"/>
		</inertial>
	</link>
	<link name="shoulder_link">
		<visual>
			<origin rpy="0 0 3.141592653589793" xyz="0 0 0"/>
			<geometry>
				<mesh filename="package://ur_description/meshes/ur3e/visual/shoulder.dae"/>
			</geometry>
		</visual>
		<collision>
			<origin rpy="0 0 3.141592653589793" xyz="0 0 0"/>
			<geometry>
				<mesh filename="package://ur_description/meshes/ur3e/collision/shoulder.stl"/>
			</geometry>
		</collision>
		<inertial>
			<mass value="2.0"/>
			<origin rpy="0 0 0" xyz="0 0 0"/>
			<inertia ixx="0.008093163429399999" ixy="0.0" ixz="0.0" iyy="0.008093163429399999" iyz="0.0" izz="0.005625"/>
		</inertial>
	</link>
	<link name="upper_arm_link">
		<visual>
			<origin rpy="1.5707963267948966 0 -1.5707963267948966" xyz="0 0 0.12"/>
			<geometry>
				<mesh filename="package://ur_description/meshes/ur3e/visual/upperarm.dae"/>
			</geometry>
		</visual>
		<collision>
			<origin rpy="1.5707963267948966 0 -1.5707963267948966" xyz="0 0 0.12"/>
			<geometry>
				<mesh filename="package://ur_description/meshes/ur3e/collision/upperarm.stl"/>
			</geometry>
		</collision>
		<inertial>
			<mass value="3.42"/>
			<origin rpy="0 1.5707963267948966 0" xyz="-0.121825 0.0 0.12"/>
			<inertia ixx="0.021728483221103233" ixy="0.0" ixz="0.0" iyy="0.021728483221103233" iyz="0.0" izz="0.00961875"/>
		</inertial>
	</link>
	<link name="forearm_link">
		<visual>
			<origin rpy="1.5707963267948966 0 -1.5707963267948966" xyz="0 0 0.027"/>
			<geometry>
				<mesh filename="package://ur_description/meshes/ur3e/visual/forearm.dae"/>
			</geometry>
		</visual>
		<collision>
			<origin rpy="1.5707963267948966 0 -1.5707963267948966" xyz="0 0 0.027"/>
			<geometry>
				<mesh filename="package://ur_description/meshes/ur3e/collision/forearm.stl"/>
			</geometry>
		</collision>
		<inertial>
			<mass value="1.26"/>
			<origin rpy="0 1.5707963267948966 0" xyz="-0.1066 0.0 0.027"/>
			<inertia ixx="0.0065445675821719194" ixy="0.0" ixz="0.0" iyy="0.0065445675821719194" iyz="0.0" izz="0.00354375"/>
		</inertial>
	</link>
	<link name="wrist_1_link">
		<visual>
			<origin rpy="1.5707963267948966 0 0" xyz="0 0 -0.104"/>
			<geometry>
				<mesh filename="package://ur_description/meshes/ur3e/visual/wrist1.dae"/>
			</geometry>
		</visual>
		<collision>
			<origin rpy="1.5707963267948966 0 0" xyz="0 0 -0.104"/>
			<geometry>
				<mesh filename="package://ur_description/meshes/ur3e/collision/wrist1.stl"/>
			</geometry>
		</collision>
		<inertial>
			<mass value="0.8"/>
			<origin rpy="0 0 0" xyz="0 0 0"/>
			<inertia ixx="0.002084999166" ixy="0.0" ixz="0.0" iyy="0.002084999166" iyz="0.0" izz="0.00225"/>
		</inertial>
	</link>
	<link name="wrist_2_link">
		<visual>
			<origin rpy="0 0 0" xyz="0 0 -0.08535"/>
			<geometry>
				<mesh filename="package://ur_description/meshes/ur3e/visual/wrist2.dae"/>
			</geometry>
		</visual>
		<collision>
			<origin rpy="0 0 0" xyz="0 0 -0.08535"/>
			<geometry>
				<mesh filename="package://ur_description/meshes/ur3e/collision/wrist2.stl"/>
			</geometry>
		</collision>
		<inertial>
			<mass value="0.8"/>
			<origin rpy="0 0 0" xyz="0 0 0"/>
			<inertia ixx="0.002084999166" ixy="0.0" ixz="0.0" iyy="0.002084999166" iyz="0.0" izz="0.00225"/>
		</inertial>
	</link>
	<link name="wrist_3_link">
		<visual>
			<origin rpy="1.5707963267948966 0 0" xyz="0 0 -0.0921"/>
			<geometry>
				<mesh filename="package://ur_description/meshes/ur3e/visual/wrist3.dae"/>
			</geometry>
		</visual>
		<collision>
			<origin rpy="1.5707963267948966 0 0" xyz="0 0 -0.0921"/>
			<geometry>
				<mesh filename="package://ur_description/meshes/ur3e/collision/wrist3.stl"/>
			</geometry>
		</collision>
		<inertial>
			<mass value="0.35"/>
			<origin rpy="0 0 0" xyz="0.0 0.0 -0.02"/>
			<inertia ixx="0.00013626661215999998" ixy="0.0" ixz="0.0" iyy="0.00013626661215999998" iyz="0.0" izz="0.0001792"/>
		</inertial>
	</link>
	<!-- base_joint fixes base_link to the environment -->
	<joint name="base_joint" type="fixed">
		<origin rpy="0 0 0" xyz="0 0 0"/>
		<parent link="world"/>
		<child link="base_link"/>
	</joint>
	<!-- joints - main serial chain -->
	<joint name="base_link-base_link_inertia" type="fixed">
		<parent link="base_link"/>
		<child link="base_link_inertia"/>
		<!-- 'base_link' is REP-103 aligned (so X+ forward), while the internal frames of the robot/controller have X+ pointing backwards. Use the joint between 'base_link' and 'base_link_inertia' (a dummy link/frame) to introduce the necessary rotation over Z (of pi rad). -->
		<origin rpy="0 0 3.141592653589793" xyz="0 0 0"/>
	</joint>
	<joint name="shoulder_pan_joint" type="revolute">
		<parent link="base_link_inertia"/>
		<child link="shoulder_link"/>
		<origin rpy="0 0 0" xyz="0 0 0.15185"/>
		<axis xyz="0 0 1"/>
		<limit effort="56.0" lower="-6.283185307179586" upper="6.283185307179586" velocity="3.141592653589793"/>
		<safety_controller k_position="20" k_velocity="0.0" soft_lower_limit="-6.133185307179586" soft_upper_limit="6.133185307179586"/>
		<dynamics damping="0" friction="0"/>
	</joint>
	<joint name="shoulder_lift_joint" type="revolute">
		<parent link="shoulder_link"/>
		<child link="upper_arm_link"/>
		<origin rpy="1.570796327 0 0" xyz="0 0 0"/>
		<axis xyz="0 0 1"/>
		<limit effort="56.0" lower="-6.283185307179586" upper="6.283185307179586" velocity="3.141592653589793"/>
		<safety_controller k_position="20" k_velocity="0.0" soft_lower_limit="-6.133185307179586" soft_upper_limit="6.133185307179586"/>
		<dynamics damping="0" friction="0"/>
	</joint>
	<joint name="elbow_joint" type="revolute">
		<parent link="upper_arm_link"/>
		<child link="forearm_link"/>
		<origin rpy="0 0 0" xyz="-0.24355 0 0"/>
		<axis xyz="0 0 1"/>
		<limit effort="28.0" lower="-3.141592653589793" upper="3.141592653589793" velocity="3.141592653589793"/>
		<safety_controller k_position="20" k_velocity="0.0" soft_lower_limit="-2.991592653589793" soft_upper_limit="2.991592653589793"/>
		<dynamics damping="0" friction="0"/>
	</joint>
	<joint name="wrist_1_joint" type="revolute">
		<parent link="forearm_link"/>
		<child link="wrist_1_link"/>
		<origin rpy="0 0 0" xyz="-0.2132 0 0.13105"/>
		<axis xyz="0 0 1"/>
		<limit effort="12.0" lower="-6.283185307179586" upper="6.283185307179586" velocity="6.283185307179586"/>
		<safety_controller k_position="20" k_velocity="0.0" soft_lower_limit="-6.133185307179586" soft_upper_limit="6.133185307179586"/>
		<dynamics damping="0" friction="0"/>
	</joint>
	<joint name="wrist_2_joint" type="revolute">
		<parent link="wrist_1_link"/>
		<child link="wrist_2_link"/>
		<origin rpy="1.570796327 0 0" xyz="0 -0.08535 -1.750557762378351e-11"/>
		<axis xyz="0 0 1"/>
		<limit effort="12.0" lower="-6.283185307179586" upper="6.283185307179586" velocity="6.283185307179586"/>
		<safety_controller k_position="20" k_velocity="0.0" soft_lower_limit="-6.133185307179586" soft_upper_limit="6.133185307179586"/>
		<dynamics damping="0" friction="0"/>
	</joint>
	<joint name="wrist_3_joint" type="revolute">
		<parent link="wrist_2_link"/>
		<child link="wrist_3_link"/>
		<origin rpy="1.570796326589793 3.141592653589793 3.141592653589793" xyz="0 0.0921 -1.8890025766262e-11"/>
		<axis xyz="0 0 1"/>
		<limit effort="12.0" lower="-6.283185307179586" upper="6.283185307179586" velocity="6.283185307179586"/>
		<safety_controller k_position="20" k_velocity="0.0" soft_lower_limit="-6.133185307179586" soft_upper_limit="6.133185307179586"/>
		<dynamics damping="0" friction="0"/>
	</joint>
	<link name="ft_frame"/>
	<joint name="wrist_3_link-ft_frame" type="fixed">
		<parent link="wrist_3_link"/>
		<child link="ft_frame"/>
		<origin rpy="3.141592653589793 0 0" xyz="0 0 0"/>
	</joint>
	<!-- ROS-Industrial 'base' frame - base_link to UR 'Base' Coordinates transform -->
	<link name="base"/>
	<joint name="base_link-base_fixed_joint" type="fixed">
		<!-- Note the rotation over Z of pi radians - as base_link is REP-103 aligned (i.e., has X+ forward, Y+ left and Z+ up), this is needed to correctly align 'base' with the 'Base' coordinate system of the UR controller. -->
		<origin rpy="0 0 3.141592653589793" xyz="0 0 0"/>
		<parent link="base_link"/>
		<child link="base"/>
	</joint>
	<!-- ROS-Industrial 'flange' frame - attachment point for EEF models -->
	<link name="flange"/>
	<joint name="wrist_3-flange" type="fixed">
		<parent link="wrist_3_link"/>
		<child link="flange"/>
		<origin rpy="0 -1.5707963267948966 -1.5707963267948966" xyz="0 0 0"/>
	</joint>
	<!-- ROS-Industrial 'tool0' frame - all-zeros tool frame -->
	<link name="tool0"/>
	<joint name="flange-tool0" type="fixed">
		<!-- default toolframe - X+ left, Y+ up, Z+ front -->
		<origin rpy="1.5707963267948966 0 1.5707963267948966" xyz="0 0 0"/>
		<parent link="flange"/>
		<child link="tool0"/>
	</joint>
	<joint name="gripper_bracket_joint" type="fixed">
		<origin rpy="0 0 1.57" xyz="-0.009 0 0.05"/>
		<parent link="wrist_3_link"/>
		<child link="gripper_bracket_link"/>
	</joint>
	<link name="gripper_bracket_link">
		<inertial>
			<inertia ixx="0.0001" ixy="0.0" ixz="0.0" iyy="0.0001" iyz="0.0" izz="0.0001"/>
			<mass value="0.001"/>
		</inertial>
		<visual>
			<origin rpy="0 0 0" xyz="0 0 0"/>
			<geometry>
				<mesh filename="package://system_description/meshes/gripper_bracket_with_screws.stl" scale="0.001 0.001 0.001"/>
			</geometry>
			<material name="LightGrey">
				<color rgba="0.7 0.7 0.7 1.0"/>
			</material>
		</visual>
		<collision>
			<origin rpy="0 0 0" xyz="0 0 0"/>
			<geometry>
				<mesh filename="package://system_description/meshes/gripper_bracket_with_screws.stl" scale="0.001 0.001 0.001"/>
			</geometry>
		</collision>
	</link>
	<!-- camera -->
	<gazebo reference="gripper_bracket_link">
		<material>Gazebo/DarkGrey</material>
	</gazebo>
	<!-- rg2ft joint -->
	<joint name="rg2ft_joint" type="fixed">
		<!-- <origin xyz="0.045 -0.0085 0" rpy="1.5792 0 0"/> -->
		<origin rpy="1.57 -1.57 1.57" xyz="0.009 0 0.05"/>
		<parent link="tool0"/>
		<child link="rg2ft_body_link"/>
	</joint>
	<link name="rg2ft_body_link">
		<!-- <origin rpy="0 0 0" xyz="0.0 0.0 0.05"/> -->
		<inertial>
			<inertia ixx="0.01" ixy="0.0" ixz="0.0" iyy="0.01" iyz="0.0" izz="0.01"/>
			<mass value="0.5"/>
		</inertial>
		<gravity>1</gravity>
		<visual>
			<origin rpy="1.57 0 1.57" xyz="0 0 0"/>
			<geometry>
				<!-- <box size="0.1 0.2 0.1"/> -->
				<mesh filename="package://onrobot_description/meshes/rg2ft_body.stl" scale="0.001 0.001 0.001"/>
			</geometry>
			<material name="LightGrey">
				<color rgba="0.7 0.7 0.7 1.0"/>
			</material>
		</visual>
		<collision>
			<origin rpy="0 0 0" xyz="0.018 0 -0.015"/>
			<geometry>
				<!-- <mesh filename="package://onrobot_description/meshes/rg2ft_body.stl" scale="0.001 0.001 0.001"/> -->
				<box size="0.118 0.07 0.05"/>
			</geometry>
		</collision>
		<!-- cable protect -->
		<collision>
			<origin rpy="1.57 0 0" xyz="0.008 0.04 -0.034"/>
			<geometry>
				<cylinder length="0.03" radius="0.005"/>
			</geometry>
		</collision>
	</link>
	<!-- left finger -->
	<joint name="body_left_finger_joint" type="revolute">
		<!-- <origin rpy="0 0 -0.78539" xyz="0.0 0.1 0"/> -->
		<origin rpy="0 0 0" xyz="0.05 0.03 0"/>
		<parent link="rg2ft_body_link"/>
		<child link="left_finger_link"/>
		<axis xyz="0 0 1"/>
		<limit effort="330.0" lower="-1.0" upper="1.0" velocity="3.14"/>
		<!-- <dynamics friction="0.1"/> -->
		<dynamics damping="0.02" friction="0.1"/>
	</joint>
	<link name="left_finger_link">
		<inertial>
			<inertia ixx="0.01" ixy="0.0" ixz="0.0" iyy="0.01" iyz="0.0" izz="0.01"/>
			<!-- <inertia ixx="0.00001079999568" ixy="0.0" ixz="0.0" iyy="0.00004379998248" iyz="0.0" izz="0.00004379998248"/> -->
			<mass value="0.072"/>
		</inertial>
		<gravity>1</gravity>
		<visual>
			<origin rpy="1.57 0 1.57" xyz="-0.05 -0.03 0"/>
			<geometry>
				<mesh filename="package://onrobot_description/meshes/rg2ft_left_finger.stl" scale="0.001 0.001 0.001"/>
				<!-- <box size="0.1 0.3 0.1"/> -->
			</geometry>
			<material name="LightGrey">
				<color rgba="0.7 0.7 0.7 1.0"/>
			</material>
		</visual>
		<collision>
			<origin rpy="0 0 0.8" xyz="0.03 0 -0.01"/>
			<geometry>
				<!-- <mesh filename="package://onrobot_description/meshes/rg2ft_left_finger.stl" scale="0.001 0.001 0.001"/> -->
				<box size="0.08 0.03 0.03"/>
			</geometry>
		</collision>
	</link>
	<joint name="left_finger_tip_joint" type="revolute">
		<!-- <origin rpy="0 0 -0.78539" xyz="0 0.3 0"/> -->
		<origin rpy="1.57 0 1.57" xyz="0.056 0.022 0"/>
		<parent link="left_finger_link"/>
		<child link="left_finger_tip_link"/>
		<!-- <axis xyz="0 0 1" /> -->
		<axis xyz="0 1 0"/>
		<limit effort="330.0" lower="-1.0" upper="1.0" velocity="3.14"/>
		<!-- <limit lower="-1.0" upper="1.0" effort="3.0" velocity="3.14"/> -->
		<dynamics friction="0.1"/>
	</joint>
	<link name="left_finger_tip_link">
		<inertial>
			<inertia ixx="0.01" ixy="0.0" ixz="0.0" iyy="0.01" iyz="0.0" izz="0.01"/>
			<!-- <inertia ixx="0.00000285991179" ixy="0.0" ixz="0.0" iyy="0.00000285991179" iyz="0.0" izz="0.000003864747209"/> -->
			<mass value="0.03435330852"/>
		</inertial>
		<gravity>1</gravity>
		<visual>
			<origin rpy="0 0 0" xyz="-0.05 0 -0.105"/>
			<geometry>
				<mesh filename="package://onrobot_description/meshes/rg2ft_left_sensor.stl" scale="0.001 0.001 0.001"/>
				<!-- <box size="0.1 0.2 0.1"/> -->
			</geometry>
			<material name="LightGrey">
				<color rgba="0.7 0.7 0.7 1.0"/>
			</material>
		</visual>
		<collision>
			<!-- <origin rpy="0 0 0" xyz="-0.05 0 -0.105"/> -->
			<origin rpy="0 1.57 0" xyz="-0.003 -0.009 0.028"/>
			<geometry>
				<!-- <mesh filename="package://onrobot_description/meshes/rg2ft_left_sensor.stl" scale="0.001 0.001 0.001"/> -->
				<cylinder length="0.018" radius="0.015"/>
			</geometry>
		</collision>
	</link>
	<!-- right finger -->
	<joint name="body_right_finger_joint" type="revolute">
		<!-- <origin rpy="0 0 0" xyz="0.05 0.03 0"/> *** left -->
		<origin rpy="0 0 0" xyz="0.05 -0.03 0"/>
		<parent link="rg2ft_body_link"/>
		<child link="right_finger_link"/>
		<axis xyz="0 0 1"/>
		<limit effort="330.0" lower="-1.0" upper="1.0" velocity="3.14"/>
		<!-- <limit lower="-1.0" upper="1.0" effort="3.0" velocity="3.14"/> -->
		<!-- <mimic joint="body_left_finger_joint" multiplier="-1" offset="0" /> -->
		<dynamics damping="0.02" friction="0.1"/>
		<!-- <dynamics damping="0.02" friction="0.1" /> -->
	</joint>
	<link name="right_finger_link">
		<inertial>
			<inertia ixx="0.01" ixy="0.0" ixz="0.0" iyy="0.01" iyz="0.0" izz="0.01"/>
			<!-- <inertia ixx="0.00001079999568" ixy="0.0" ixz="0.0" iyy="0.00004379998248" iyz="0.0" izz="0.00004379998248"/> -->
			<mass value="0.072"/>
		</inertial>
		<gravity>1</gravity>
		<visual>
			<origin rpy="1.57 0 1.57" xyz="-0.05 0.03 0"/>
			<geometry>
				<mesh filename="package://onrobot_description/meshes/rg2ft_right_finger.stl" scale="0.001 0.001 0.001"/>
				<!-- <box size="0.1 0.3 0.1"/> -->
			</geometry>
			<material name="LightGrey">
				<color rgba="0.7 0.7 0.7 1.0"/>
			</material>
		</visual>
		<collision>
			<origin rpy="0 0 -0.8" xyz="0.03 0 -0.01"/>
			<geometry>
				<box size="0.08 0.03 0.03"/>
			</geometry>
		</collision>
	</link>
	<joint name="right_finger_tip_joint" type="revolute">
		<origin rpy="1.57 0 1.57" xyz="0.056 -0.022 0"/>
		<parent link="right_finger_link"/>
		<child link="right_finger_tip_link"/>
		<axis xyz="0 1 0"/>
		<limit effort="330.0" lower="-1.0" upper="1.0" velocity="3.14"/>
		<!-- <limit lower="-1.0" upper="1.0" effort="3.0" velocity="3.14"/> -->
		<!-- <mimic joint="body_left_finger_joint" multiplier="-1" offset="0" /> -->
		<dynamics friction="0.1"/>
	</joint>
	<link name="right_finger_tip_link">
		<inertial>
			<inertia ixx="0.01" ixy="0.0" ixz="0.0" iyy="0.01" iyz="0.0" izz="0.01"/>
			<!-- <inertia ixx="0.00000285991179" ixy="0.0" ixz="0.0" iyy="0.00000285991179" iyz="0.0" izz="0.000003864747209"/> -->
			<mass value="0.03435330852"/>
		</inertial>
		<gravity>1</gravity>
		<visual>
			<origin rpy="0 0 0" xyz="0.05 0 -0.105"/>
			<geometry>
				<mesh filename="package://onrobot_description/meshes/rg2ft_right_sensor.stl" scale="0.001 0.001 0.001"/>
			</geometry>
			<material name="LightGrey">
				<color rgba="0.7 0.7 0.7 1.0"/>
			</material>
		</visual>
		<collision>
			<origin rpy="0 1.57 0" xyz="0.003 -0.009 0.028"/>
			<geometry>
				<!-- <mesh filename="package://onrobot/meshes/rg2ft_right_sensor.stl" scale="0.001 0.001 0.001"/> -->
				<cylinder length="0.018" radius="0.015"/>
			</geometry>
		</collision>
	</link>
	<!-- end effector -->
	<joint name="rg2ft_eef_joint" type="fixed">
		<!-- <origin rpy="0 0 0" xyz="0.195 0.0 0.0"/> -->
		<origin rpy="0 0 0" xyz="0.195 0.0 0.0"/>
		<parent link="rg2ft_body_link"/>
		<child link="rg2ft_eef_link"/>
	</joint>
	<link name="rg2ft_eef_link"/>
	<!-- transmission -->
	<!-- <xacro:rg2ft_transmission prefix="" /> -->
	<transmission name="body_left_finger_trans">
		<type>transmission_interface/SimpleTransmission</type>
		<joint name="body_left_finger_joint">
			<!-- <hardwareInterface>hardware_interface/PositionJointInterface</hardwareInterface> -->
			<hardwareInterface>hardware_interface/EffortJointInterface</hardwareInterface>
		</joint>
		<actuator name="body_left_finger_motor">
			<mechanicalReduction>1</mechanicalReduction>
		</actuator>
	</transmission>
	<transmission name="body_right_finger_trans">
		<type>transmission_interface/SimpleTransmission</type>
		<joint name="body_right_finger_joint">
			<!-- <hardwareInterface>hardware_interface/PositionJointInterface</hardwareInterface> -->
			<hardwareInterface>hardware_interface/EffortJointInterface</hardwareInterface>
		</joint>
		<actuator name="body_right_finger_motor">
			<mechanicalReduction>1</mechanicalReduction>
		</actuator>
	</transmission>
	<transmission name="left_finger_tip_trans">
		<type>transmission_interface/SimpleTransmission</type>
		<joint name="left_finger_tip_joint">
			<!-- <hardwareInterface>hardware_interface/PositionJointInterface</hardwareInterface> -->
			<hardwareInterface>hardware_interface/EffortJointInterface</hardwareInterface>
		</joint>
		<actuator name="left_finger_tip_motor">
			<mechanicalReduction>1</mechanicalReduction>
		</actuator>
	</transmission>
	<transmission name="right_finger_tip_trans">
		<type>transmission_interface/SimpleTransmission</type>
		<joint name="right_finger_tip_joint">
			<!-- <hardwareInterface>hardware_interface/PositionJointInterface</hardwareInterface> -->
			<hardwareInterface>hardware_interface/EffortJointInterface</hardwareInterface>
		</joint>
		<actuator name="right_finger_tip_motor">
			<mechanicalReduction>1</mechanicalReduction>
		</actuator>
	</transmission>
	<joint name="camera_holder_joint" type="fixed">
		<!-- xyz fel-le ; hatra-elore ; balra-jobbra -->
		<origin rpy="0 3.14 1.57" xyz="-0.0375 -0.070 -0.003"/>
		<parent link="gripper_bracket_link"/>
		<child link="camera_holder_link"/>
	</joint>
	<link name="camera_holder_link">
		<visual>
			<origin rpy="0 0 0" xyz="0 0 0"/>
			<geometry>
				<mesh filename="package://system_description/meshes/skamera_ur_new.stl" scale="0.001 0.001 0.001"/>
			</geometry>
			<!-- <material name="LightGrey"><color rgba="0.7 0.7 0.7 1.0"/></material> -->
			<material name="Brickred">
				<color rgba="0.87 0.25 0.11 1.0"/>
			</material>
		</visual>
		<collision>
			<origin rpy="0 0 0" xyz="0 0 0"/>
			<geometry>
				<mesh filename="package://system_description/meshes/skamera_ur_new.stl" scale="0.001 0.001 0.001"/>
			</geometry>
		</collision>
	</link>
	<!-- camera -->
	<!-- <gazebo reference="camera_holder_link"><material>Gazebo/Orange</material></gazebo> -->
	<!-- camera body, with origin at bottom screw mount -->
	<joint name="camera_joint" type="fixed">
		<origin rpy="0 1.57 0" xyz="-0.022 -0.039 -0.01"/>
		<parent link="camera_holder_link"/>
		<child link="camera_bottom_screw_frame"/>
	</joint>
	<link name="camera_bottom_screw_frame"/>
	<joint name="camera_link_joint" type="fixed">
		<origin rpy="0 0 0" xyz="0.011150000000000002 0.0475 0.0145"/>
		<parent link="camera_bottom_screw_frame"/>
		<child link="camera_link"/>
	</joint>
	<link name="camera_link">
		<visual>
			<!-- the mesh origin is at front plate in between the two infrared camera axes -->
			<!-- <origin xyz="${d455_zero_depth_to_glass-d455_cam_depth/2} ${-d455_cam_depth_py} 0" rpy="0 0 0"/> -->
			<origin rpy="1.5707963267948966 0 1.5707963267948966" xyz="0.0046500000000000005 -0.0475 0"/>
			<geometry>
				<!-- <box size="${d455_cam_depth} ${d455_cam_width} ${d455_cam_height}"/> -->
				<mesh filename="file:///home/martzi/yang_ws/install/realsense2_description/share/realsense2_description/meshes/d455.stl" scale="0.001 0.001 0.001"/>
			</geometry>
			<material name="aluminum"/>
		</visual>
		<collision>
			<origin rpy="0 0 0" xyz="-0.00845 -0.0475 0"/>
			<geometry>
				<box size="0.026 0.124 0.029"/>
			</geometry>
		</collision>
		<inertial>
			<!-- The following are not reliable values, and should not be used for modeling -->
			<mass value="0.072"/>
			<origin xyz="0 0 0"/>
			<inertia ixx="0.003881243" ixy="0.0" ixz="0.0" iyy="0.000498940" iyz="0.0" izz="0.003879257"/>
		</inertial>
	</link>
	<yang>
		<!-- Realsense D455 L2 network topology -->
		<robot-network:networks>
			<network-id>network_level</network-id>
			<layer2:l2-topology>
				<element>template</element>
			</layer2:l2-topology>
			<supporting-network>
				<network-ref>sensor_d455_device_level</network-ref>
				<tf-parent>camera_holder_link</tf-parent>
			</supporting-network>
			<node>
				<node-id>sensor_d455_L2</node-id>
				<layer2:l2-node-attributes>
					<bandwidth>5</bandwidth>
					<delay>2</delay>
				</layer2:l2-node-attributes>
				<supporting-node>
					<network-ref>sensor_d455_device_level</network-ref>
					<node-ref>sensor_d455_L1</node-ref>
				</supporting-node>
				<robot-network-topology:termination-point>
					<tp-id>usb_1</tp-id>
					<supporting-termination-point>
						<network-ref>sensor_d455_device_level</network-ref>
						<node-ref>sensor_d455_L1</node-ref>
						<tp-ref>usb-typec_1</tp-ref>
					</supporting-termination-point>
					<layer2:l2-termination-point-attributes>
						<tp-type>usb30</tp-type>
						<bandwidth>4800</bandwidth>
						<jitter>8</jitter>
						<packet_loss>0.005</packet_loss>
						<reliability>0.98</reliability>
						<cost>25</cost>
					</layer2:l2-termination-point-attributes>
				</robot-network-topology:termination-point>
			</node>
		</robot-network:networks>
		<!-- Realsense D455 L1 network topology -->
		<robot-network:networks>
			<network-id>device_level</network-id>
			<layer1:l1-topology>
				<element>template</element>
			</layer1:l1-topology>
			<node>
				<node-id>sensor_d455_L1</node-id>
				<layer1:l1-node-attributes>
					<device-type>camera</device-type>
					<phy-port-num>2</phy-port-num>
					<wireless-access>0</wireless-access>
				</layer1:l1-node-attributes>
				<robot-network-topology:termination-point>
					<tp-id>usb_1</tp-id>
					<layer1:l1-termination-point-attributes>
						<connector-type>usb_type-C</connector-type>
						<connector-format>female</connector-format>
					</layer1:l1-termination-point-attributes>
				</robot-network-topology:termination-point>
			</node>
		</robot-network:networks>
	</yang>
	<!-- <xacro:macro name="nuc" params="parent L1_id L2_id L1_network_id L2_network_id"> -->
	<joint name="nuc_joint" type="fixed">
		<origin rpy="0 0 0" xyz="-1 1 0"/>
		<parent link="world"/>
		<child link="nuc_link"/>
	</joint>
	<link name="nuc_link">
		<visual>
			<origin rpy="0 0 0" xyz="0 0 0"/>
			<geometry>
				<mesh filename="package://nuc_description/meshes/intel_nuc.stl" scale="0.001 0.001 0.001"/>
			</geometry>
			<material name="LightGrey">
				<color rgba="0.7 0.7 0.7 1.0"/>
			</material>
		</visual>
		<collision>
			<origin rpy="0 0 0" xyz="0 0 0"/>
			<geometry>
				<mesh filename="package://nuc_description/meshes/intel_nuc.stl" scale="0.001 0.001 0.001"/>
			</geometry>
		</collision>
	</link>
	<yang>
		<!-- NUC L2 network topology -->
		<robot-network:networks>
			<network-id>network_level</network-id>
			<layer2:l2-topology>
				<element>template</element>
			</layer2:l2-topology>
			<supporting-network>
				<network-ref>nuc_device_level</network-ref>
				<tf-parent>world</tf-parent>
			</supporting-network>
			<node>
				<node-id>nuc_L2</node-id>
				<layer2:l2-node-attributes>
					<bandwidth>1</bandwidth>
					<delay>2</delay>
				</layer2:l2-node-attributes>
				<supporting-node>
					<network-ref>nuc_L2</network-ref>
					<node-ref>nuc_L1</node-ref>
				</supporting-node>
				<robot-network-topology:termination-point>
					<tp-id>usb_1</tp-id>
					<supporting-termination-point>
						<network-ref>nuc_device_level</network-ref>
						<node-ref>nuc_L1</node-ref>
						<tp-ref>usb_1</tp-ref>
					</supporting-termination-point>
					<layer2:l2-termination-point-attributes>
						<tp-type>usb30</tp-type>
						<bandwidth>4800</bandwidth>
						<jitter>8</jitter>
						<packet_loss>0.005</packet_loss>
						<reliability>0.98</reliability>
						<cost>25</cost>
					</layer2:l2-termination-point-attributes>
				</robot-network-topology:termination-point>
				<robot-network-topology:termination-point>
					<tp-id>usb_2</tp-id>
					<supporting-termination-point>
						<network-ref>nuc_device_level</network-ref>
						<node-ref>nuc_L1</node-ref>
						<tp-ref>usb_2</tp-ref>
					</supporting-termination-point>
					<layer2:l2-termination-point-attributes>
						<tp-type>usb30</tp-type>
						<bandwidth>4800</bandwidth>
						<jitter>8</jitter>
						<packet_loss>0.005</packet_loss>
						<reliability>0.98</reliability>
						<cost>25</cost>
					</layer2:l2-termination-point-attributes>
				</robot-network-topology:termination-point>
				<robot-network-topology:termination-point>
					<tp-id>usb_3</tp-id>
					<supporting-termination-point>
						<network-ref>nuc_device_level</network-ref>
						<node-ref>nuc_L1</node-ref>
						<tp-ref>usb_3</tp-ref>
					</supporting-termination-point>
					<layer2:l2-termination-point-attributes>
						<tp-type>usb30</tp-type>
						<bandwidth>4800</bandwidth>
						<jitter>8</jitter>
						<packet_loss>0.005</packet_loss>
						<reliability>0.98</reliability>
						<cost>25</cost>
					</layer2:l2-termination-point-attributes>
				</robot-network-topology:termination-point>
				<robot-network-topology:termination-point>
					<tp-id>usb_4</tp-id>
					<supporting-termination-point>
						<network-ref>nuc_device_level</network-ref>
						<node-ref>nuc_L1</node-ref>
						<tp-ref>usb_3</tp-ref>
					</supporting-termination-point>
					<layer2:l2-termination-point-attributes>
						<tp-type>usb30</tp-type>
						<bandwidth>4800</bandwidth>
						<jitter>8</jitter>
						<packet_loss>0.005</packet_loss>
						<reliability>0.98</reliability>
						<cost>25</cost>
					</layer2:l2-termination-point-attributes>
				</robot-network-topology:termination-point>
				<robot-network-topology:termination-point>
					<tp-id>usb_5</tp-id>
					<supporting-termination-point>
						<network-ref>nuc_device_level</network-ref>
						<node-ref>nuc_L1</node-ref>
						<tp-ref>usb_3</tp-ref>
					</supporting-termination-point>
					<layer2:l2-termination-point-attributes>
						<tp-type>usb30</tp-type>
						<bandwidth>4800</bandwidth>
						<jitter>8</jitter>
						<packet_loss>0.005</packet_loss>
						<reliability>0.98</reliability>
						<cost>25</cost>
					</layer2:l2-termination-point-attributes>
				</robot-network-topology:termination-point>
				<robot-network-topology:termination-point>
					<tp-id>eth_1</tp-id>
					<supporting-termination-point>
						<network-ref>nuc_device_level</network-ref>
						<node-ref>nuc_L1</node-ref>
						<tp-ref>eth_1</tp-ref>
					</supporting-termination-point>
					<layer2:l2-termination-point-attributes>
						<tp-type>cat6</tp-type>
						<bandwidth>10000</bandwidth>
						<jitter>5</jitter>
						<packet_loss>0.005</packet_loss>
						<reliability>0.98</reliability>
						<cost>50</cost>
					</layer2:l2-termination-point-attributes>
				</robot-network-topology:termination-point>
				<robot-network-topology:termination-point>
					<tp-id>wireless_1</tp-id>
					<supporting-termination-point>
						<network-ref>nuc_device_level</network-ref>
						<node-ref>nuc_L1</node-ref>
						<tp-ref>wireless_1</tp-ref>
					</supporting-termination-point>
					<layer2:l2-termination-point-attributes>
						<tp-type>wifi4</tp-type>
						<bandwidth>600</bandwidth>
						<jitter>10</jitter>
						<packet_loss>0.02</packet_loss>
						<reliability>0.95</reliability>
						<cost>10</cost>
					</layer2:l2-termination-point-attributes>
				</robot-network-topology:termination-point>
				<robot-network-topology:termination-point>
					<tp-id>wireless_2</tp-id>
					<supporting-termination-point>
						<network-ref>nuc_device_level</network-ref>
						<node-ref>nuc_L1</node-ref>
						<tp-ref>wireless_2</tp-ref>
					</supporting-termination-point>
					<layer2:l2-termination-point-attributes>
						<tp-type>wifi5</tp-type>
						<bandwidth>3500</bandwidth>
						<jitter>15</jitter>
						<packet_loss>0.02</packet_loss>
						<reliability>0.95</reliability>
						<cost>20</cost>
					</layer2:l2-termination-point-attributes>
				</robot-network-topology:termination-point>
			</node>
		</robot-network:networks>
		<!-- NUC L1 network topology -->
		<robot-network:networks>
			<network-id>device_level</network-id>
			<layer1:l1-topology>
				<element>template</element>
			</layer1:l1-topology>
			<node>
				<node-id>nuc_L1</node-id>
				<layer1:l1-node-attributes>
					<device-type>pc</device-type>
					<phy-port-num>6</phy-port-num>
					<wireless-access>1</wireless-access>
				</layer1:l1-node-attributes>
				<robot-network-topology:termination-point>
					<tp-id>usb_1</tp-id>
					<layer1:l1-termination-point-attributes>
						<connector-type>usb-std_A</connector-type>
						<connector-format>female</connector-format>
					</layer1:l1-termination-point-attributes>
				</robot-network-topology:termination-point>
				<robot-network-topology:termination-point>
					<tp-id>usb_2</tp-id>
					<layer1:l1-termination-point-attributes>
						<connector-type>usb-std_A</connector-type>
						<connector-format>female</connector-format>
					</layer1:l1-termination-point-attributes>
				</robot-network-topology:termination-point>
				<robot-network-topology:termination-point>
					<tp-id>usb_3</tp-id>
					<layer1:l1-termination-point-attributes>
						<connector-type>usb-std_A</connector-type>
						<connector-format>female</connector-format>
					</layer1:l1-termination-point-attributes>
				</robot-network-topology:termination-point>
				<robot-network-topology:termination-point>
					<tp-id>usb_4</tp-id>
					<layer1:l1-termination-point-attributes>
						<connector-type>usb-type_C</connector-type>
						<connector-format>female</connector-format>
					</layer1:l1-termination-point-attributes>
				</robot-network-topology:termination-point>
				<robot-network-topology:termination-point>
					<tp-id>usb_5</tp-id>
					<layer1:l1-termination-point-attributes>
						<connector-type>usb-type_C</connector-type>
						<connector-format>female</connector-format>
					</layer1:l1-termination-point-attributes>
				</robot-network-topology:termination-point>
				<robot-network-topology:termination-point>
					<tp-id>eth_1</tp-id>
					<layer1:l1-termination-point-attributes>
						<connector-type>rj45</connector-type>
						<connector-format>female</connector-format>
					</layer1:l1-termination-point-attributes>
				</robot-network-topology:termination-point>
				<robot-network-topology:termination-point>
					<tp-id>wireless_1</tp-id>
					<layer1:l1-termination-point-attributes>
						<connector-type>wifi_4</connector-type>
						<connector-format>wireless</connector-format>
					</layer1:l1-termination-point-attributes>
				</robot-network-topology:termination-point>
				<robot-network-topology:termination-point>
					<tp-id>wireless_2</tp-id>
					<layer1:l1-termination-point-attributes>
						<connector-type>wifi_5</connector-type>
						<connector-format>wireless</connector-format>
					</layer1:l1-termination-point-attributes>
				</robot-network-topology:termination-point>
			</node>
		</robot-network:networks>
	</yang>
	<joint name="poeswitch_joint" type="fixed">
		<origin rpy="0 0 0" xyz="-1 1.5 0"/>
		<parent link="world"/>
		<child link="poeswitch_link"/>
	</joint>
	<link name="poeswitch_link">
		<visual>
			<origin rpy="0 0 0" xyz="0 0 0"/>
			<geometry>
				<mesh filename="package://poesw_description/meshes/TP-LINK_5_Port_POE_Switch_Blank_TL-SG1005P.stl" scale="0.001 0.001 0.001"/>
			</geometry>
			<material name="LightGrey">
				<color rgba="0.7 0.7 0.7 1.0"/>
			</material>
		</visual>
		<collision>
			<origin rpy="0 0 0" xyz="0 0 0"/>
			<geometry>
				<mesh filename="package://poesw_description/meshes/TP-LINK_5_Port_POE_Switch_Blank_TL-SG1005P.stl" scale="0.001 0.001 0.001"/>
			</geometry>
		</collision>
	</link>
	<yang>
		<!-- POE Switch L2 network topology -->
		<robot-network:networks>
			<network-id>network_level</network-id>
			<layer2:l2-topology>
				<element>template</element>
			</layer2:l2-topology>
			<supporting-network>
				<network-ref>poesw_device_level</network-ref>
				<tf-parent>world</tf-parent>
			</supporting-network>
			<node>
				<node-id>poesw_L2</node-id>
				<layer2:l2-node-attributes>
					<bandwidth>1</bandwidth>
					<delay>0</delay>
				</layer2:l2-node-attributes>
				<supporting-node>
					<network-ref>poesw_L2</network-ref>
					<node-ref>poesw_L1</node-ref>
				</supporting-node>
				<robot-network-topology:termination-point>
					<tp-id>eth_1</tp-id>
					<supporting-termination-point>
						<network-ref>poesw_device_level</network-ref>
						<node-ref>poesw_L1</node-ref>
						<tp-ref>eth_1</tp-ref>
					</supporting-termination-point>
					<layer2:l2-termination-point-attributes>
						<tp-type>cat6</tp-type>
						<bandwidth>10000</bandwidth>
						<jitter>5</jitter>
						<packet_loss>0.005</packet_loss>
						<reliability>0.98</reliability>
						<cost>50</cost>
					</layer2:l2-termination-point-attributes>
				</robot-network-topology:termination-point>
				<robot-network-topology:termination-point>
					<tp-id>eth_2</tp-id>
					<supporting-termination-point>
						<network-ref>poesw_device_level</network-ref>
						<node-ref>poesw_L1</node-ref>
						<tp-ref>eth_2</tp-ref>
					</supporting-termination-point>
					<layer2:l2-termination-point-attributes>
						<tp-type>cat6</tp-type>
						<bandwidth>10000</bandwidth>
						<jitter>5</jitter>
						<packet_loss>0.005</packet_loss>
						<reliability>0.98</reliability>
						<cost>50</cost>
					</layer2:l2-termination-point-attributes>
				</robot-network-topology:termination-point>
				<robot-network-topology:termination-point>
					<tp-id>eth_3</tp-id>
					<supporting-termination-point>
						<network-ref>poesw_device_level</network-ref>
						<node-ref>poesw_L1</node-ref>
						<tp-ref>eth_3</tp-ref>
					</supporting-termination-point>
					<layer2:l2-termination-point-attributes>
						<tp-type>cat6</tp-type>
						<bandwidth>10000</bandwidth>
						<jitter>5</jitter>
						<packet_loss>0.005</packet_loss>
						<reliability>0.98</reliability>
						<cost>50</cost>
					</layer2:l2-termination-point-attributes>
				</robot-network-topology:termination-point>
				<robot-network-topology:termination-point>
					<tp-id>eth_4</tp-id>
					<supporting-termination-point>
						<network-ref>poesw_device_level</network-ref>
						<node-ref>poesw_L1</node-ref>
						<tp-ref>eth_4</tp-ref>
					</supporting-termination-point>
					<layer2:l2-termination-point-attributes>
						<tp-type>cat6</tp-type>
						<bandwidth>10000</bandwidth>
						<jitter>5</jitter>
						<packet_loss>0.005</packet_loss>
						<reliability>0.98</reliability>
						<cost>50</cost>
					</layer2:l2-termination-point-attributes>
				</robot-network-topology:termination-point>
				<robot-network-topology:termination-point>
					<tp-id>eth_5</tp-id>
					<supporting-termination-point>
						<network-ref>poesw_device_level</network-ref>
						<node-ref>poesw_L1</node-ref>
						<tp-ref>eth_5</tp-ref>
					</supporting-termination-point>
					<layer2:l2-termination-point-attributes>
						<tp-type>cat6</tp-type>
						<bandwidth>10000</bandwidth>
						<jitter>5</jitter>
						<packet_loss>0.005</packet_loss>
						<reliability>0.98</reliability>
						<cost>50</cost>
					</layer2:l2-termination-point-attributes>
				</robot-network-topology:termination-point>
			</node>
		</robot-network:networks>
		<!-- POE Switch L1 network topology -->
		<robot-network:networks>
			<network-id>device_level</network-id>
			<layer1:l1-topology>
				<element>template</element>
			</layer1:l1-topology>
			<node>
				<node-id>poesw_L1</node-id>
				<layer1:l1-node-attributes>
					<device-type>switch</device-type>
					<phy-port-num>5</phy-port-num>
					<wireless-access>0</wireless-access>
				</layer1:l1-node-attributes>
				<robot-network-topology:termination-point>
					<tp-id>eth_1</tp-id>
					<layer1:l1-termination-point-attributes>
						<connector-type>rj45</connector-type>
						<connector-format>female</connector-format>
					</layer1:l1-termination-point-attributes>
				</robot-network-topology:termination-point>
				<robot-network-topology:termination-point>
					<tp-id>eth_2</tp-id>
					<layer1:l1-termination-point-attributes>
						<connector-type>rj45</connector-type>
						<connector-format>female</connector-format>
					</layer1:l1-termination-point-attributes>
				</robot-network-topology:termination-point>
				<robot-network-topology:termination-point>
					<tp-id>eth_3</tp-id>
					<layer1:l1-termination-point-attributes>
						<connector-type>rj45</connector-type>
						<connector-format>female</connector-format>
					</layer1:l1-termination-point-attributes>
				</robot-network-topology:termination-point>
				<robot-network-topology:termination-point>
					<tp-id>eth_4</tp-id>
					<layer1:l1-termination-point-attributes>
						<connector-type>rj45</connector-type>
						<connector-format>female</connector-format>
					</layer1:l1-termination-point-attributes>
				</robot-network-topology:termination-point>
				<robot-network-topology:termination-point>
					<tp-id>eth_5</tp-id>
					<layer1:l1-termination-point-attributes>
						<connector-type>rj45</connector-type>
						<connector-format>female</connector-format>
					</layer1:l1-termination-point-attributes>
				</robot-network-topology:termination-point>
			</node>
		</robot-network:networks>
	</yang>
	<joint name="flightrack_joint" type="fixed">
		<origin rpy="1.57 0 1.57" xyz="-2 2 0"/>
		<parent link="world"/>
		<child link="flightrack_link"/>
	</joint>
	<link name="flightrack_link">
		<visual>
			<origin rpy="0 0 0" xyz="0 0 0"/>
			<geometry>
				<mesh filename="package://flightrack_description/meshes/server-rack.stl" scale="0.001 0.001 0.001"/>
			</geometry>
			<material name="LightGrey">
				<color rgba="0.7 0.7 0.7 1.0"/>
			</material>
		</visual>
		<collision>
			<origin rpy="0 0 0" xyz="0 0 0"/>
			<geometry>
				<mesh filename="package://flightrack_description/meshes/server-rack.stl" scale="0.001 0.001 0.001"/>
			</geometry>
		</collision>
	</link>
	<yang>
		<!-- Flightrack L2 network topology -->
		<robot-network:networks>
			<network-id>network_level</network-id>
			<layer2:l2-topology>
				<element>template</element>
			</layer2:l2-topology>
			<supporting-network>
				<network-ref>flightrack_device_level</network-ref>
				<tf-parent>world</tf-parent>
			</supporting-network>
			<node>
				<node-id>flightrack_L2</node-id>
				<layer2:l2-node-attributes>
					<bandwidth>20</bandwidth>
					<delay>1</delay>
				</layer2:l2-node-attributes>
				<supporting-node>
					<network-ref>flightrack_L2</network-ref>
					<node-ref>flightrack_L1</node-ref>
				</supporting-node>
				<robot-network-topology:termination-point>
					<tp-id>eth_1</tp-id>
					<supporting-termination-point>
						<network-ref>flightrack_device_level</network-ref>
						<node-ref>flightrack_L1</node-ref>
						<tp-ref>eth_1</tp-ref>
					</supporting-termination-point>
					<layer2:l2-termination-point-attributes>
						<tp-type>cat6</tp-type>
						<bandwidth>10000</bandwidth>
						<jitter>5</jitter>
						<packet_loss>0.005</packet_loss>
						<reliability>0.98</reliability>
						<cost>50</cost>
					</layer2:l2-termination-point-attributes>
				</robot-network-topology:termination-point>
				<robot-network-topology:termination-point>
					<tp-id>eth_2</tp-id>
					<supporting-termination-point>
						<network-ref>flightrack_device_level</network-ref>
						<node-ref>flightrack_L1</node-ref>
						<tp-ref>eth_2</tp-ref>
					</supporting-termination-point>
					<layer2:l2-termination-point-attributes>
						<tp-type>cat6</tp-type>
						<bandwidth>10000</bandwidth>
						<jitter>5</jitter>
						<packet_loss>0.005</packet_loss>
						<reliability>0.98</reliability>
						<cost>50</cost>
					</layer2:l2-termination-point-attributes>
				</robot-network-topology:termination-point>
				<robot-network-topology:termination-point>
					<tp-id>eth_3</tp-id>
					<supporting-termination-point>
						<network-ref>flightrack_device_level</network-ref>
						<node-ref>flightrack_L1</node-ref>
						<tp-ref>eth_3</tp-ref>
					</supporting-termination-point>
					<layer2:l2-termination-point-attributes>
						<tp-type>cat6</tp-type>
						<bandwidth>10000</bandwidth>
						<jitter>5</jitter>
						<packet_loss>0.005</packet_loss>
						<reliability>0.98</reliability>
						<cost>50</cost>
					</layer2:l2-termination-point-attributes>
				</robot-network-topology:termination-point>
				<robot-network-topology:termination-point>
					<tp-id>eth_4</tp-id>
					<supporting-termination-point>
						<network-ref>flightrack_device_level</network-ref>
						<node-ref>flightrack_L1</node-ref>
						<tp-ref>eth_4</tp-ref>
					</supporting-termination-point>
					<layer2:l2-termination-point-attributes>
						<tp-type>cat6</tp-type>
						<bandwidth>10000</bandwidth>
						<jitter>5</jitter>
						<packet_loss>0.005</packet_loss>
						<reliability>0.98</reliability>
						<cost>50</cost>
					</layer2:l2-termination-point-attributes>
				</robot-network-topology:termination-point>
				<robot-network-topology:termination-point>
					<tp-id>eth_5</tp-id>
					<supporting-termination-point>
						<network-ref>flightrack_device_level</network-ref>
						<node-ref>flightrack_L1</node-ref>
						<tp-ref>eth_5</tp-ref>
					</supporting-termination-point>
					<layer2:l2-termination-point-attributes>
						<tp-type>cat6</tp-type>
						<bandwidth>10000</bandwidth>
						<jitter>5</jitter>
						<packet_loss>0.005</packet_loss>
						<reliability>0.98</reliability>
						<cost>50</cost>
					</layer2:l2-termination-point-attributes>
				</robot-network-topology:termination-point>
			</node>
		</robot-network:networks>
		<!-- Flightrack L1 network topology -->
		<robot-network:networks>
			<network-id>device_level</network-id>
			<layer1:l1-topology>
				<element>template</element>
			</layer1:l1-topology>
			<node>
				<node-id>flightrack_L1</node-id>
				<layer1:l1-node-attributes>
					<device-type>switch</device-type>
					<phy-port-num>5</phy-port-num>
					<wireless-access>0</wireless-access>
				</layer1:l1-node-attributes>
				<robot-network-topology:termination-point>
					<tp-id>eth_1</tp-id>
					<layer1:l1-termination-point-attributes>
						<connector-type>rj45</connector-type>
						<connector-format>female</connector-format>
					</layer1:l1-termination-point-attributes>
				</robot-network-topology:termination-point>
				<robot-network-topology:termination-point>
					<tp-id>eth_2</tp-id>
					<layer1:l1-termination-point-attributes>
						<connector-type>rj45</connector-type>
						<connector-format>female</connector-format>
					</layer1:l1-termination-point-attributes>
				</robot-network-topology:termination-point>
				<robot-network-topology:termination-point>
					<tp-id>eth_3</tp-id>
					<layer1:l1-termination-point-attributes>
						<connector-type>rj45</connector-type>
						<connector-format>female</connector-format>
					</layer1:l1-termination-point-attributes>
				</robot-network-topology:termination-point>
				<robot-network-topology:termination-point>
					<tp-id>eth_4</tp-id>
					<layer1:l1-termination-point-attributes>
						<connector-type>rj45</connector-type>
						<connector-format>female</connector-format>
					</layer1:l1-termination-point-attributes>
				</robot-network-topology:termination-point>
				<robot-network-topology:termination-point>
					<tp-id>eth_5</tp-id>
					<layer1:l1-termination-point-attributes>
						<connector-type>rj45</connector-type>
						<connector-format>female</connector-format>
					</layer1:l1-termination-point-attributes>
				</robot-network-topology:termination-point>
			</node>
		</robot-network:networks>
	</yang>
	<joint name="nw-5g-modem_joint" type="fixed">
		<origin rpy="0 0 3.14" xyz="-1 1.2 0"/>
		<parent link="world"/>
		<child link="nw-5g-modem_link"/>
	</joint>
	<link name="nw-5g-modem_link">
		<visual>
			<origin rpy="0 0 0" xyz="0 0 0"/>
			<geometry>
				<mesh filename="package://nw-5g-modem_description/meshes/usb-dongle.stl" scale="0.01 0.01 0.01"/>
			</geometry>
			<material name="LightGrey">
				<color rgba="0.7 0.7 0.7 1.0"/>
			</material>
		</visual>
		<collision>
			<origin rpy="0 0 0" xyz="0 0 0"/>
			<geometry>
				<mesh filename="package://nw-5g-modem_description/meshes/usb-dongle.stl" scale="0.01 0.01 0.01"/>
			</geometry>
		</collision>
	</link>
	<yang>
		<!-- 5gmodem L2 network topology -->
		<robot-network:networks>
			<network-id>network_level</network-id>
			<layer2:l2-topology>
				<element>template</element>
			</layer2:l2-topology>
			<supporting-network>
				<network-ref>nw-5g-modem-device_level</network-ref>
				<tf-parent>world</tf-parent>
			</supporting-network>
			<node>
				<node-id>nw-5g-modem-L2</node-id>
				<layer2:l2-node-attributes>
					<bandwidth>2</bandwidth>
					<delay>8</delay>
				</layer2:l2-node-attributes>
				<supporting-node>
					<network-ref>nw-5g-modem-device_level</network-ref>
					<node-ref>nw-5g-modem-L1</node-ref>
				</supporting-node>
				<robot-network-topology:termination-point>
					<tp-id>usb_1</tp-id>
					<supporting-termination-point>
						<network-ref>nw-5g-modem-device_level</network-ref>
						<node-ref>nw-5g-modem-L1</node-ref>
						<tp-ref>usb_1</tp-ref>
					</supporting-termination-point>
					<layer2:l2-termination-point-attributes>
						<tp-type>usb30</tp-type>
						<bandwidth>4800</bandwidth>
						<jitter>8</jitter>
						<packet_loss>0.005</packet_loss>
						<reliability>0.98</reliability>
						<cost>25</cost>
					</layer2:l2-termination-point-attributes>
				</robot-network-topology:termination-point>
				<robot-network-topology:termination-point>
					<tp-id>wireless_1</tp-id>
					<supporting-termination-point>
						<network-ref>nw-5g-modem-device_level</network-ref>
						<node-ref>nw-5g-modem-L1</node-ref>
						<tp-ref>wireless_1</tp-ref>
					</supporting-termination-point>
					<layer2:l2-termination-point-attributes>
						<tp-type>5g_rel15</tp-type>
						<bandwidth>10000</bandwidth>
						<jitter>1</jitter>
						<packet_loss>0.001</packet_loss>
						<reliability>0.999</reliability>
						<cost>100</cost>
					</layer2:l2-termination-point-attributes>
				</robot-network-topology:termination-point>
			</node>
		</robot-network:networks>
		<!-- 5gmodem L1 network topology -->
		<robot-network:networks>
			<network-id>device_level</network-id>
			<layer1:l1-topology>
				<element>template</element>
			</layer1:l1-topology>
			<node>
				<node-id>nw-5g-modem-L1</node-id>
				<layer1:l1-node-attributes>
					<device-type>nw-5g-modem</device-type>
					<phy-port-num>1</phy-port-num>
					<wireless-access>1</wireless-access>
				</layer1:l1-node-attributes>
				<robot-network-topology:termination-point>
					<tp-id>usb_1</tp-id>
					<layer1:l1-termination-point-attributes>
						<connector-type>usb-std_A</connector-type>
						<connector-format>female</connector-format>
					</layer1:l1-termination-point-attributes>
				</robot-network-topology:termination-point>
				<robot-network-topology:termination-point>
					<tp-id>wireless_1</tp-id>
					<layer1:l1-termination-point-attributes>
						<connector-type>wireless</connector-type>
						<connector-format>wireless</connector-format>
					</layer1:l1-termination-point-attributes>
				</robot-network-topology:termination-point>
			</node>
		</robot-network:networks>
	</yang>
	<joint name="radiodot_joint" type="fixed">
		<origin rpy="0 0 0" xyz="-1 1.2 2"/>
		<parent link="world"/>
		<child link="radiodot_link"/>
	</joint>
	<link name="radiodot_link">
		<visual>
			<origin rpy="0 0 0" xyz="0 0 0"/>
			<geometry>
				<mesh filename="package://radiodot_description/meshes/radio_dot.stl" scale="0.01 0.01 0.01"/>
			</geometry>
			<material name="LightGrey">
				<color rgba="0.7 0.7 0.7 1.0"/>
			</material>
		</visual>
		<collision>
			<origin rpy="0 0 0" xyz="0 0 0"/>
			<geometry>
				<mesh filename="package://radiodot_description/meshes/radio_dot.stl" scale="0.01 0.01 0.01"/>
			</geometry>
		</collision>
	</link>
	<yang>
		<!-- radiodot L2 network topology -->
		<robot-network:networks>
			<network-id>network_level</network-id>
			<layer2:l2-topology>
				<element>template</element>
			</layer2:l2-topology>
			<supporting-network>
				<network-ref>radiodot-device_level</network-ref>
				<tf-parent>world</tf-parent>
			</supporting-network>
			<node>
				<node-id>radiodot_L2</node-id>
				<layer2:l2-node-attributes>
					<bandwidth>10</bandwidth>
					<delay>0</delay>
				</layer2:l2-node-attributes>
				<supporting-node>
					<network-ref>radiodot_L2</network-ref>
					<node-ref>radiodot_L1</node-ref>
				</supporting-node>
				<robot-network-topology:termination-point>
					<tp-id>eth_1</tp-id>
					<supporting-termination-point>
						<network-ref>radiodot-device_level</network-ref>
						<node-ref>radiodot_L1</node-ref>
						<tp-ref>eth_1</tp-ref>
					</supporting-termination-point>
					<layer2:l2-termination-point-attributes>
						<tp-type>cat6</tp-type>
						<bandwidth>10000</bandwidth>
						<jitter>5</jitter>
						<packet_loss>0.005</packet_loss>
						<reliability>0.98</reliability>
						<cost>50</cost>
					</layer2:l2-termination-point-attributes>
				</robot-network-topology:termination-point>
				<robot-network-topology:termination-point>
					<tp-id>wireless_1</tp-id>
					<supporting-termination-point>
						<network-ref>radiodot-device_level</network-ref>
						<node-ref>radiodot_L1</node-ref>
						<tp-ref>wireless_1</tp-ref>
					</supporting-termination-point>
					<layer2:l2-termination-point-attributes>
						<tp-type>5g_rel15</tp-type>
						<bandwidth>10000</bandwidth>
						<jitter>1</jitter>
						<packet_loss>0.001</packet_loss>
						<reliability>0.999</reliability>
						<cost>100</cost>
					</layer2:l2-termination-point-attributes>
				</robot-network-topology:termination-point>
			</node>
		</robot-network:networks>
		<!-- radiodot L1 network topology -->
		<robot-network:networks>
			<network-id>device_level</network-id>
			<layer1:l1-topology>
				<element>template</element>
			</layer1:l1-topology>
			<node>
				<node-id>radiodot_L1</node-id>
				<layer1:l1-node-attributes>
					<device-type>radiodot</device-type>
					<phy-port-num>1</phy-port-num>
					<wireless-access>0</wireless-access>
				</layer1:l1-node-attributes>
				<robot-network-topology:termination-point>
					<tp-id>eth_1</tp-id>
					<layer1:l1-termination-point-attributes>
						<connector-type>rj45</connector-type>
						<connector-format>female</connector-format>
					</layer1:l1-termination-point-attributes>
				</robot-network-topology:termination-point>
				<robot-network-topology:termination-point>
					<tp-id>wireless_1</tp-id>
					<layer1:l1-termination-point-attributes>
						<connector-type>wireless</connector-type>
						<connector-format>wireless</connector-format>
					</layer1:l1-termination-point-attributes>
				</robot-network-topology:termination-point>
			</node>
		</robot-network:networks>
	</yang>
	<joint name="mikrotik_joint" type="fixed">
		<origin rpy="0 0 0" xyz="-1.1 1 0"/>
		<parent link="world"/>
		<child link="mikrotik_link"/>
	</joint>
	<link name="mikrotik_link">
		<visual>
			<origin rpy="0 0 0" xyz="0 0 0"/>
			<geometry>
				<mesh filename="package://mikrotik-description/meshes/Mikrotik_hAPac2_Top.stl" scale="0.001 0.001 0.001"/>
			</geometry>
			<material name="LightGrey">
				<color rgba="0.7 0.7 0.7 1.0"/>
			</material>
		</visual>
		<collision>
			<origin rpy="0 0 0" xyz="0 0 0"/>
			<geometry>
				<mesh filename="package://mikrotik-description/meshes/Mikrotik_hAPac2_Top.stl" scale="0.001 0.001 0.001"/>
			</geometry>
		</collision>
	</link>
	<yang>
		<!-- Mikrotik L2 network topology -->
		<robot-network:networks>
			<network-id>network_level</network-id>
			<layer2:l2-topology>
				<element>template</element>
			</layer2:l2-topology>
			<supporting-network>
				<network-ref>mikrotik_device_level</network-ref>
				<tf-parent>world</tf-parent>
			</supporting-network>
			<node>
				<node-id>mikrotik_L2</node-id>
				<layer2:l2-node-attributes>
					<bandwidth>1</bandwidth>
					<delay>0</delay>
				</layer2:l2-node-attributes>
				<supporting-node>
					<network-ref>mikrotik_device_level</network-ref>
					<node-ref>mikrotik_L1</node-ref>
				</supporting-node>
				<robot-network-topology:termination-point>
					<tp-id>eth_1</tp-id>
					<supporting-termination-point>
						<network-ref>mikrotik_device_level</network-ref>
						<node-ref>mikrotik_L1</node-ref>
						<tp-ref>eth_1</tp-ref>
					</supporting-termination-point>
					<layer2:l2-termination-point-attributes>
						<tp-type>cat6</tp-type>
						<bandwidth>10000</bandwidth>
						<jitter>5</jitter>
						<packet_loss>0.005</packet_loss>
						<reliability>0.98</reliability>
						<cost>50</cost>
					</layer2:l2-termination-point-attributes>
				</robot-network-topology:termination-point>
				<robot-network-topology:termination-point>
					<tp-id>eth_2</tp-id>
					<supporting-termination-point>
						<network-ref>mikrotik_device_level</network-ref>
						<node-ref>mikrotik_L1</node-ref>
						<tp-ref>eth_2</tp-ref>
					</supporting-termination-point>
					<layer2:l2-termination-point-attributes>
						<tp-type>cat6</tp-type>
						<bandwidth>10000</bandwidth>
						<jitter>5</jitter>
						<packet_loss>0.005</packet_loss>
						<reliability>0.98</reliability>
						<cost>50</cost>
					</layer2:l2-termination-point-attributes>
				</robot-network-topology:termination-point>
				<robot-network-topology:termination-point>
					<tp-id>eth_3</tp-id>
					<supporting-termination-point>
						<network-ref>mikrotik_device_level</network-ref>
						<node-ref>mikrotik_L1</node-ref>
						<tp-ref>eth_3</tp-ref>
					</supporting-termination-point>
					<layer2:l2-termination-point-attributes>
						<tp-type>cat6</tp-type>
						<bandwidth>10000</bandwidth>
						<jitter>5</jitter>
						<packet_loss>0.005</packet_loss>
						<reliability>0.98</reliability>
						<cost>50</cost>
					</layer2:l2-termination-point-attributes>
				</robot-network-topology:termination-point>
				<robot-network-topology:termination-point>
					<tp-id>eth_4</tp-id>
					<supporting-termination-point>
						<network-ref>mikrotik_device_level</network-ref>
						<node-ref>mikrotik_L1</node-ref>
						<tp-ref>eth_4</tp-ref>
					</supporting-termination-point>
					<layer2:l2-termination-point-attributes>
						<tp-type>cat6</tp-type>
						<bandwidth>10000</bandwidth>
						<jitter>5</jitter>
						<packet_loss>0.005</packet_loss>
						<reliability>0.98</reliability>
						<cost>50</cost>
					</layer2:l2-termination-point-attributes>
				</robot-network-topology:termination-point>
				<robot-network-topology:termination-point>
					<tp-id>eth_5</tp-id>
					<supporting-termination-point>
						<network-ref>mikrotik_device_level</network-ref>
						<node-ref>mikrotik_L1</node-ref>
						<tp-ref>eth_5</tp-ref>
					</supporting-termination-point>
					<layer2:l2-termination-point-attributes>
						<tp-type>cat6</tp-type>
						<bandwidth>10000</bandwidth>
						<jitter>5</jitter>
						<packet_loss>0.005</packet_loss>
						<reliability>0.98</reliability>
						<cost>50</cost>
					</layer2:l2-termination-point-attributes>
				</robot-network-topology:termination-point>
				<robot-network-topology:termination-point>
					<tp-id>usb_1</tp-id>
					<supporting-termination-point>
						<network-ref>mikrotik_device_level</network-ref>
						<node-ref>mikrotik_L1</node-ref>
						<tp-ref>usb_1</tp-ref>
					</supporting-termination-point>
					<layer2:l2-termination-point-attributes>
						<tp-type>usb30</tp-type>
						<bandwidth>4800</bandwidth>
						<jitter>8</jitter>
						<packet_loss>0.005</packet_loss>
						<reliability>0.98</reliability>
						<cost>25</cost>
					</layer2:l2-termination-point-attributes>
				</robot-network-topology:termination-point>
				<robot-network-topology:termination-point>
					<tp-id>wireless_1</tp-id>
					<supporting-termination-point>
						<network-ref>mikrotik_device_level</network-ref>
						<node-ref>mikrotik_L1</node-ref>
						<tp-ref>wireless_1</tp-ref>
					</supporting-termination-point>
					<layer2:l2-termination-point-attributes>
						<tp-type>wifi4</tp-type>
						<bandwidth>600</bandwidth>
						<jitter>10</jitter>
						<packet_loss>0.02</packet_loss>
						<reliability>0.95</reliability>
						<cost>10</cost>
					</layer2:l2-termination-point-attributes>
				</robot-network-topology:termination-point>
				<robot-network-topology:termination-point>
					<tp-id>wireless_2</tp-id>
					<supporting-termination-point>
						<network-ref>mikrotik_device_level</network-ref>
						<node-ref>mikrotik_L1</node-ref>
						<tp-ref>wireless_2</tp-ref>
					</supporting-termination-point>
					<layer2:l2-termination-point-attributes>
						<tp-type>wifi5</tp-type>
						<bandwidth>3500</bandwidth>
						<jitter>15</jitter>
						<packet_loss>0.02</packet_loss>
						<reliability>0.95</reliability>
						<cost>20</cost>
					</layer2:l2-termination-point-attributes>
				</robot-network-topology:termination-point>
			</node>
		</robot-network:networks>
		<!-- Mikrotik L1 network topology -->
		<robot-network:networks>
			<network-id>device_level</network-id>
			<layer1:l1-topology>
				<element>template</element>
			</layer1:l1-topology>
			<node>
				<node-id>mikrotik_L1</node-id>
				<layer1:l1-node-attributes>
					<device-type>router</device-type>
					<phy-port-num>6</phy-port-num>
					<wireless-access>1</wireless-access>
				</layer1:l1-node-attributes>
				<robot-network-topology:termination-point>
					<tp-id>eth_1</tp-id>
					<layer1:l1-termination-point-attributes>
						<connector-type>rj45</connector-type>
						<connector-format>female</connector-format>
					</layer1:l1-termination-point-attributes>
				</robot-network-topology:termination-point>
				<robot-network-topology:termination-point>
					<tp-id>eth_2</tp-id>
					<layer1:l1-termination-point-attributes>
						<connector-type>rj45</connector-type>
						<connector-format>female</connector-format>
					</layer1:l1-termination-point-attributes>
				</robot-network-topology:termination-point>
				<robot-network-topology:termination-point>
					<tp-id>eth_3</tp-id>
					<layer1:l1-termination-point-attributes>
						<connector-type>rj45</connector-type>
						<connector-format>female</connector-format>
					</layer1:l1-termination-point-attributes>
				</robot-network-topology:termination-point>
				<robot-network-topology:termination-point>
					<tp-id>eth_4</tp-id>
					<layer1:l1-termination-point-attributes>
						<connector-type>rj45</connector-type>
						<connector-format>female</connector-format>
					</layer1:l1-termination-point-attributes>
				</robot-network-topology:termination-point>
				<robot-network-topology:termination-point>
					<tp-id>eth_5</tp-id>
					<layer1:l1-termination-point-attributes>
						<connector-type>rj45</connector-type>
						<connector-format>female</connector-format>
					</layer1:l1-termination-point-attributes>
				</robot-network-topology:termination-point>
				<robot-network-topology:termination-point>
					<tp-id>usb_1</tp-id>
					<layer1:l1-termination-point-attributes>
						<connector-type>usb-std_A</connector-type>
						<connector-format>female</connector-format>
					</layer1:l1-termination-point-attributes>
				</robot-network-topology:termination-point>
				<robot-network-topology:termination-point>
					<tp-id>wireless_1</tp-id>
					<layer1:l1-termination-point-attributes>
						<connector-type>wifi_4</connector-type>
						<connector-format>wireless</connector-format>
					</layer1:l1-termination-point-attributes>
				</robot-network-topology:termination-point>
				<robot-network-topology:termination-point>
					<tp-id>wireless_2</tp-id>
					<layer1:l1-termination-point-attributes>
						<connector-type>wifi_5</connector-type>
						<connector-format>wireless</connector-format>
					</layer1:l1-termination-point-attributes>
				</robot-network-topology:termination-point>
			</node>
		</robot-network:networks>
	</yang>
	<joint name="rpi4_link" type="fixed">
		<origin rpy="0 0 0" xyz="-1 1.8 0"/>
		<parent link="world"/>
		<child link="rpi4_link"/>
	</joint>
	<link name="rpi4_link">
		<visual>
			<origin rpy="0 0 0" xyz="0 0 0"/>
			<geometry>
				<mesh filename="package://raspi4b_description/meshes/raspberry_pi_4_model_b.stl" scale="0.001 0.001 0.001"/>
			</geometry>
			<material name="LightGrey">
				<color rgba="0.7 0.7 0.7 1.0"/>
			</material>
		</visual>
		<collision>
			<origin rpy="0 0 0" xyz="0 0 0"/>
			<geometry>
				<mesh filename="package://raspi4b_description/meshes/raspberry_pi_4_model_b.stl" scale="0.001 0.001 0.001"/>
			</geometry>
		</collision>
	</link>
	<yang>
		<!-- Raspi4B L2 network topology -->
		<robot-network:networks>
			<network-id>network_level</network-id>
			<layer2:l2-topology>
				<element>template</element>
			</layer2:l2-topology>
			<supporting-network>
				<network-ref>rpi4-device_level</network-ref>
				<tf-parent>world</tf-parent>
			</supporting-network>
			<node>
				<node-id>rpi4_L2</node-id>
				<layer2:l2-node-attributes>
					<bandwidth>1</bandwidth>
					<delay>10</delay>
				</layer2:l2-node-attributes>
				<supporting-node>
					<network-ref>rpi4-device_level</network-ref>
					<node-ref>rpi4_L1</node-ref>
				</supporting-node>
				<robot-network-topology:termination-point>
					<tp-id>usb_1</tp-id>
					<supporting-termination-point>
						<network-ref>rpi4-device_level</network-ref>
						<node-ref>rpi4_L1</node-ref>
						<tp-ref>usb_1</tp-ref>
					</supporting-termination-point>
					<layer2:l2-termination-point-attributes>
						<tp-type>usb30</tp-type>
						<bandwidth>4800</bandwidth>
						<jitter>8</jitter>
						<packet_loss>0.005</packet_loss>
						<reliability>0.98</reliability>
						<cost>25</cost>
					</layer2:l2-termination-point-attributes>
				</robot-network-topology:termination-point>
				<robot-network-topology:termination-point>
					<tp-id>usb_2</tp-id>
					<supporting-termination-point>
						<network-ref>rpi4-device_level</network-ref>
						<node-ref>rpi4_L1</node-ref>
						<tp-ref>usb_2</tp-ref>
					</supporting-termination-point>
					<layer2:l2-termination-point-attributes>
						<tp-type>usb30</tp-type>
						<bandwidth>4800</bandwidth>
						<jitter>8</jitter>
						<packet_loss>0.005</packet_loss>
						<reliability>0.98</reliability>
						<cost>25</cost>
					</layer2:l2-termination-point-attributes>
				</robot-network-topology:termination-point>
				<robot-network-topology:termination-point>
					<tp-id>usb_3</tp-id>
					<supporting-termination-point>
						<network-ref>rpi4-device_level</network-ref>
						<node-ref>rpi4_L1</node-ref>
						<tp-ref>usb_3</tp-ref>
					</supporting-termination-point>
					<layer2:l2-termination-point-attributes>
						<tp-type>usb20</tp-type>
						<bandwidth>480</bandwidth>
						<jitter>15</jitter>
						<packet_loss>0.02</packet_loss>
						<reliability>0.9</reliability>
						<cost>5</cost>
					</layer2:l2-termination-point-attributes>
				</robot-network-topology:termination-point>
				<robot-network-topology:termination-point>
					<tp-id>usb_4</tp-id>
					<supporting-termination-point>
						<network-ref>rpi4-device_level</network-ref>
						<node-ref>rpi4_L1</node-ref>
						<tp-ref>usb_4</tp-ref>
					</supporting-termination-point>
					<layer2:l2-termination-point-attributes>
						<tp-type>usb20</tp-type>
						<bandwidth>480</bandwidth>
						<jitter>15</jitter>
						<packet_loss>0.02</packet_loss>
						<reliability>0.9</reliability>
						<cost>5</cost>
					</layer2:l2-termination-point-attributes>
				</robot-network-topology:termination-point>
				<robot-network-topology:termination-point>
					<tp-id>eth_1</tp-id>
					<supporting-termination-point>
						<network-ref>rpi4-device_level</network-ref>
						<node-ref>rpi4_L1</node-ref>
						<tp-ref>eth_1</tp-ref>
					</supporting-termination-point>
					<layer2:l2-termination-point-attributes>
						<tp-type>cat5e</tp-type>
						<bandwidth>1000</bandwidth>
						<jitter>10</jitter>
						<packet_loss>0.01</packet_loss>
						<reliability>0.95</reliability>
						<cost>30</cost>
					</layer2:l2-termination-point-attributes>
				</robot-network-topology:termination-point>
				<robot-network-topology:termination-point>
					<tp-id>wireless_1</tp-id>
					<supporting-termination-point>
						<network-ref>rpi4-device_level</network-ref>
						<node-ref>rpi4_L1</node-ref>
						<tp-ref>wireless_1</tp-ref>
					</supporting-termination-point>
					<layer2:l2-termination-point-attributes>
						<tp-type>wifi4</tp-type>
						<bandwidth>600</bandwidth>
						<jitter>10</jitter>
						<packet_loss>0.02</packet_loss>
						<reliability>0.95</reliability>
						<cost>10</cost>
					</layer2:l2-termination-point-attributes>
				</robot-network-topology:termination-point>
			</node>
		</robot-network:networks>
		<!-- Raspi4B L1 network topology -->
		<robot-network:networks>
			<network-id>device_level</network-id>
			<layer1:l1-topology>
				<element>template</element>
			</layer1:l1-topology>
			<node>
				<node-id>rpi4_L1</node-id>
				<layer1:l1-node-attributes>
					<device-type>rpi4</device-type>
					<phy-port-num>5</phy-port-num>
					<wireless-access>1</wireless-access>
				</layer1:l1-node-attributes>
				<robot-network-topology:termination-point>
					<tp-id>usb_1</tp-id>
					<layer1:l1-termination-point-attributes>
						<connector-type>usb-std_A</connector-type>
						<connector-format>female</connector-format>
					</layer1:l1-termination-point-attributes>
				</robot-network-topology:termination-point>
				<robot-network-topology:termination-point>
					<tp-id>usb_2</tp-id>
					<layer1:l1-termination-point-attributes>
						<connector-type>usb-std_A</connector-type>
						<connector-format>female</connector-format>
					</layer1:l1-termination-point-attributes>
				</robot-network-topology:termination-point>
				<robot-network-topology:termination-point>
					<tp-id>usb_3</tp-id>
					<layer1:l1-termination-point-attributes>
						<connector-type>usb-std_A</connector-type>
						<connector-format>female</connector-format>
					</layer1:l1-termination-point-attributes>
				</robot-network-topology:termination-point>
				<robot-network-topology:termination-point>
					<tp-id>usb_4</tp-id>
					<layer1:l1-termination-point-attributes>
						<connector-type>usb-std_A</connector-type>
						<connector-format>female</connector-format>
					</layer1:l1-termination-point-attributes>
				</robot-network-topology:termination-point>
				<robot-network-topology:termination-point>
					<tp-id>eth_1</tp-id>
					<layer1:l1-termination-point-attributes>
						<connector-type>rj45</connector-type>
						<connector-format>female</connector-format>
					</layer1:l1-termination-point-attributes>
				</robot-network-topology:termination-point>
				<robot-network-topology:termination-point>
					<tp-id>wireless_1</tp-id>
					<layer1:l1-termination-point-attributes>
						<connector-type>wifi_4</connector-type>
						<connector-format>wireless</connector-format>
					</layer1:l1-termination-point-attributes>
				</robot-network-topology:termination-point>
			</node>
		</robot-network:networks>
	</yang>
	<!-- <srdf>=$(find system_description)/config/actual_config.srdf</srdf> -->
	<yang>
		<!-- robot-network-topology-link -->
		<robot-network:networks>
			<network-id>topology_level</network-id>
			<layer1:l1-topology>
				<element>template</element>
			</layer1:l1-topology>
			<robot-network-topology:link>
				<robot-network-topology:link-id>poesw_L2-mikrotik_L2-link</robot-network-topology:link-id>
				<layer1:l1-link-attributes>
					<type>wired</type>
					<reconfig>hw_supported</reconfig>
				</layer1:l1-link-attributes>
				<source>
					<source-node>poesw_L2</source-node>
					<source-tp>eth_1</source-tp>
				</source>
				<destination>
					<dest-node>mikrotik_L2</dest-node>
					<dest-tp>eth_1</dest-tp>
				</destination>
			</robot-network-topology:link>
		</robot-network:networks>
	</yang>
	<yang>
		<!-- robot-network-topology-link -->
		<robot-network:networks>
			<network-id>topology_level</network-id>
			<layer1:l1-topology>
				<element>template</element>
			</layer1:l1-topology>
			<robot-network-topology:link>
				<robot-network-topology:link-id>mikrotik_L2-rpi4_L2-link</robot-network-topology:link-id>
				<layer1:l1-link-attributes>
					<type>wired</type>
					<reconfig>hw_supported</reconfig>
				</layer1:l1-link-attributes>
				<source>
					<source-node>mikrotik_L2</source-node>
					<source-tp>eth_2</source-tp>
				</source>
				<destination>
					<dest-node>rpi4_L2</dest-node>
					<dest-tp>eth_1</dest-tp>
				</destination>
			</robot-network-topology:link>
		</robot-network:networks>
	</yang>
	<yang>
		<!-- robot-network-topology-link -->
		<robot-network:networks>
			<network-id>topology_level</network-id>
			<layer1:l1-topology>
				<element>template</element>
			</layer1:l1-topology>
			<robot-network-topology:link>
				<robot-network-topology:link-id>sensor_d455_L2-nuc_L2-link</robot-network-topology:link-id>
				<layer1:l1-link-attributes>
					<type>wired</type>
					<reconfig>hw_supported</reconfig>
				</layer1:l1-link-attributes>
				<source>
					<source-node>sensor_d455_L2</source-node>
					<source-tp>usb_1</source-tp>
				</source>
				<destination>
					<dest-node>nuc_L2</dest-node>
					<dest-tp>usb_1</dest-tp>
				</destination>
			</robot-network-topology:link>
		</robot-network:networks>
	</yang>
	<yang>
		<!-- robot-network-topology-link -->
		<robot-network:networks>
			<network-id>topology_level</network-id>
			<layer1:l1-topology>
				<element>template</element>
			</layer1:l1-topology>
			<robot-network-topology:link>
				<robot-network-topology:link-id>nuc_L2-poesw_L2-link</robot-network-topology:link-id>
				<layer1:l1-link-attributes>
					<type>wired</type>
					<reconfig>hw_supported</reconfig>
				</layer1:l1-link-attributes>
				<source>
					<source-node>nuc_L2</source-node>
					<source-tp>eth_1</source-tp>
				</source>
				<destination>
					<dest-node>poesw_L2</dest-node>
					<dest-tp>eth_2</dest-tp>
				</destination>
			</robot-network-topology:link>
		</robot-network:networks>
	</yang>
	<yang>
		<!-- robot-network-topology-link -->
		<robot-network:networks>
			<network-id>topology_level</network-id>
			<layer1:l1-topology>
				<element>template</element>
			</layer1:l1-topology>
			<robot-network-topology:link>
				<robot-network-topology:link-id>controlbox_L2-poesw_L2-link</robot-network-topology:link-id>
				<layer1:l1-link-attributes>
					<type>wired</type>
					<reconfig>hw_supported</reconfig>
				</layer1:l1-link-attributes>
				<source>
					<source-node>controlbox_L2</source-node>
					<source-tp>eth_1</source-tp>
				</source>
				<destination>
					<dest-node>poesw_L2</dest-node>
					<dest-tp>eth_4</dest-tp>
				</destination>
			</robot-network-topology:link>
		</robot-network:networks>
	</yang>
	<yang>
		<!-- robot-network-topology-link -->
		<robot-network:networks>
			<network-id>topology_level</network-id>
			<layer1:l1-topology>
				<element>template</element>
			</layer1:l1-topology>
			<robot-network-topology:link>
				<robot-network-topology:link-id>nw-5g-modem-L2-rpi4_L2-link</robot-network-topology:link-id>
				<layer1:l1-link-attributes>
					<type>wired</type>
					<reconfig>hw_supported</reconfig>
				</layer1:l1-link-attributes>
				<source>
					<source-node>nw-5g-modem-L2</source-node>
					<source-tp>usb_1</source-tp>
				</source>
				<destination>
					<dest-node>rpi4_L2</dest-node>
					<dest-tp>usb_1</dest-tp>
				</destination>
			</robot-network-topology:link>
		</robot-network:networks>
	</yang>
	<yang>
		<!-- robot-network-topology-link -->
		<robot-network:networks>
			<network-id>topology_level</network-id>
			<layer1:l1-topology>
				<element>template</element>
			</layer1:l1-topology>
			<robot-network-topology:link>
				<robot-network-topology:link-id>nw-5g-modem-L2-radiodot_L2-link</robot-network-topology:link-id>
				<layer1:l1-link-attributes>
					<type>wireless</type>
					<reconfig>sw_supported</reconfig>
				</layer1:l1-link-attributes>
				<source>
					<source-node>nw-5g-modem-L2</source-node>
					<source-tp>wireless_1</source-tp>
				</source>
				<destination>
					<dest-node>radiodot_L2</dest-node>
					<dest-tp>wireless_1</dest-tp>
				</destination>
			</robot-network-topology:link>
		</robot-network:networks>
	</yang>
	<yang>
		<!-- robot-network-topology-link -->
		<robot-network:networks>
			<network-id>topology_level</network-id>
			<layer1:l1-topology>
				<element>template</element>
			</layer1:l1-topology>
			<robot-network-topology:link>
				<robot-network-topology:link-id>radiodot_L2-flightrack_L2-link</robot-network-topology:link-id>
				<layer1:l1-link-attributes>
					<type>wired</type>
					<reconfig>sw_supported</reconfig>
				</layer1:l1-link-attributes>
				<source>
					<source-node>radiodot_L2</source-node>
					<source-tp>eth_1</source-tp>
				</source>
				<destination>
					<dest-node>flightrack_L2</dest-node>
					<dest-tp>eth_1</dest-tp>
				</destination>
			</robot-network-topology:link>
		</robot-network:networks>
	</yang>
</robot>
